Workbook

Sheet Uitleg
B1: Schuttersvereniging St. Michiel Roeselare
B2: Clubklassement over leeftijdscategorieën en disciplines heen
B6: Instellingen
B7: Seizoen | C7: 2026 | D7: Verschijnt in de titels van het klassement
B8: Aantal tellende wedstrijden | C8: 5 | D8: De beste resultaten die meetellen (1 - 10)
B9: Schoten per wedstrijd | C9: 30 | D9: Vast: de coëfficiënten zijn berekend voor 30 schoten
B12: Zo gebruik je dit bestand
B13: 1. Vul op het tabblad 'Resultaten' per schutter de naam, de discipline (LK of LP) en de categorie in.
B14: Een schutter die beide disciplines schiet, krijgt een rij per discipline.
B15: Vul na elke wedstrijd het resultaat (30 schoten) in: LK met decimalen, LP in gehele getallen.
B16: Laat de cel leeg als de schutter niet meedeed.
B17: 2. Het tabblad 'Klassement' sorteert zichzelf en is klaar om af te drukken. De tellende resultaten zijn gemarkeerd.
B18: Alleen de gele cellen invullen, de rest wordt berekend. Rij 1 op 'Resultaten' is een voorbeeld: overschrijf of wis die.
B21: Categorieën
B22: Categorie | C22: Groep | D22: Omschrijving
B23: DUV | C23: DUV | D23: Duiveltje, < 12 jaar
B24: BEN | C24: BEN | D24: Benjamin, 12 - 13 jaar
B25: CAD | C25: CAD | D25: Cadet, 14 - 15 jaar
B26: JD | C26: JUN | D26: Junior dame, 16 - 20 jaar
B27: JH | C27: JUN | D27: Junior heer, 16 - 20 jaar
B28: D1 | C28: D1 & S1 | D28: Dame 1, 21 - 49 jaar
B29: S1 | C29: D1 & S1 | D29: Senioren 1, 21 - 49 jaar
B30: D2 | C30: D2 & S2 | D30: Dame 2, 50 - 59 jaar
B31: S2 | C31: D2 & S2 | D31: Senioren 2, 50 - 59 jaar
B32: D3 | C32: D3 & S3 | D32: Dame 3, 60+ jaar
B33: S3 | C33: D3 & S3 | D33: Senioren 3, 60+ jaar
B36: Wat betekent 'op 100 schutters'?
B37: Jongeren, senioren, luchtkarabijn en luchtpistool halen gemiddeld andere scores. Daarom wordt elk resultaat omgerekend
B38: naar een score op 100: stel dat er 100 schutters van jouw leeftijdsgroep en discipline op het Belgisch kampioenschap (BOA)
B39: meedoen, hoeveel daarvan zou je dan verslaan? Een score van 60 betekent dat je beter schiet dan 60 van de 100.
B40: Dames en heren van dezelfde leeftijd zitten in dezelfde groep: op topniveau scoren ze gelijkwaardig.
B41: De coëfficiënten staan op het tabblad 'Coëfficiënten' en worden jaarlijks bijgewerkt met de nieuwe BOA-resultaten.
B42: Gegenereerd op 30/10/2026 met github.com/BramBaert/NormalizeCompetitionResults (src/build_club_sheet.py).

Sheet Resultaten
C1: ="Resultaten clubcompetitie "&Uitleg!$C$7
C2: Gele cellen invullen: naam, discipline, categorie en resultaat (30 schoten). Leeg laten als de schutter niet meedeed. De rest wordt berekend.
E4: Geschoten (30 schoten) | O4: Op 100 schutters
AB5: =Uitleg!$C$8
A6: Nr | B6: Naam | C6: Disc. | D6: Cat. | E6: W1 | F6: W2 | G6: W3 | H6: W4 | I6: W5 | J6: W6 | K6: W7 | L6: W8 | M6: W9 | N6: W10 | O6: W1 | P6: W2 | Q6: W3 | R6: W4 | S6: W5 | T6: W6 | U6: W7 | V6: W8 | W6: W9 | X6: W10 | Y6: ="Beste "&Uitleg!$C$8 | Z6: Gemiddelde | AA6: Plaats | AB6: kol | AC6: sorteer
A7: =ROW()-6 | B7: Voorbeeld Schutter | C7: LK | D7: S2 | E7: 287.4 | F7: 291 | G7: 289.6 | H7: 284.2 | I7: 290.3 | J7: 292.1 | O7: =IF(OR($AB7="",N(E7)<=0),"",ROUND(E7*INDEX('Coëfficiënten'!$A$7:$AB$1006,MATCH(E7,INDEX('Coëfficiënten'!$A$7:$AB$1006,0,$AB7),1),$AB7+1),1)) | P7: =IF(OR($AB7="",N(F7)<=0),"",ROUND(F7*INDEX('Coëfficiënten'!$A$7:$AB$1006,MATCH(F7,INDEX('Coëfficiënten'!$A$7:$AB$1006,0,$AB7),1),$AB7+1),1)) | Q7: =IF(OR($AB7="",N(G7)<=0),"",ROUND(G7*INDEX('Coëfficiënten'!$A$7:$AB$1006,MATCH(G7,INDEX('Coëfficiënten'!$A$7:$AB$1006,0,$AB7),1),$AB7+1),1)) | R7: =IF(OR($AB7="",N(H7)<=0),"",ROUND(H7*INDEX('Coëfficiënten'!$A$7:$AB$1006,MATCH(H7,INDEX('Coëfficiënten'!$A$7:$AB$1006,0,$AB7),1),$AB7+1),1)) | S7: =IF(OR($AB7="",N(I7)<=0),"",ROUND(I7*INDEX('Coëfficiënten'!$A$7:$AB$1006,MATCH(I7,INDEX('Coëfficiënten'!$A$7:$AB$1006,0,$AB7),1),$AB7+1),1)) | T7: =IF(OR($AB7="",N(J7)<=0),"",ROUND(J7*INDEX('Coëfficiënten'!$A$7:$AB$1006,MATCH(J7,INDEX('Coëfficiënten'!$A$7:$AB$1006,0,$AB7),1),$AB7+1),1)) | U7: =IF(OR($AB7="",N(K7)<=0),"",ROUND(K7*INDEX('Coëfficiënten'!$A$7:$AB$1006,MATCH(K7,INDEX('Coëfficiënten'!$A$7:$AB$1006,0,$AB7),1),$AB7+1),1)) | V7: =IF(OR($AB7="",N(L7)<=0),"",ROUND(L7*INDEX('Coëfficiënten'!$A$7:$AB$1006,MATCH(L7,INDEX('Coëfficiënten'!$A$7:$AB$1006,0,$AB7),1),$AB7+1),1)) | ... X7: =IF(OR($AB7="",N(N7)<=0),"",ROUND(N7*INDEX('Coëfficiënten'!$A$7:$AB$1006,MATCH(N7,INDEX('Coëfficiënten'!$A$7:$AB$1006,0,$AB7),1),$AB7+1),1)) | Y7: =IF(OR($B7="",COUNT($O7:$X7)=0),"",IFERROR(LARGE($O7:$X7,1),0)*($AB$5>=1)+IFERROR(LARGE($O7:$X7,2),0)*($AB$5>=2)+IFERROR(LARGE($O7:$X7,3),0)*($AB$5>=3)+IFERROR(LARGE($O7:$X7,4),0)*($AB$5>=4)+IFERROR(LARGE($O7:$X7,5),0)*($AB$5>=5)+IFERROR(LARGE($O7:$X7,6),0)*($AB$5>=6)+IFERROR(LARGE($O7:$X7,7),0)*($AB$5>=7)+IFERROR(LARGE($O7:$X7,8),0)*($AB$5>=8)+IFERROR(LARGE($O7:$X7,9),0)*($AB$5>=9)+IFERROR(LARGE($O7:$X7,10),0)*($AB$5>=10)) | Z7: =IF(N($Y7)=0,"",$Y7/MIN($AB$5,COUNT($O7:$X7))) | AA7: =IF(N($Y7)=0,"",RANK($Y7,$Y$7:$Y$66)) | AB7: =IF(OR($C7="",$D7=""),"",IFERROR(MATCH($C7&"|"&VLOOKUP($D7,Uitleg!$B$23:$C$33,2,FALSE),'Coëfficiënten'!$A$5:$AB$5,0),"")) | AC7: =IF(N($Y7)=0,"",$Y7+(67-ROW())/1000000000)
A8: =ROW()-6 | O8: =IF(OR($AB8="",N(E8)<=0),"",ROUND(E8*INDEX('Coëfficiënten'!$A$7:$AB$1006,MATCH(E8,INDEX('Coëfficiënten'!$A$7:$AB$1006,0,$AB8),1),$AB8+1),1)) | P8: =IF(OR($AB8="",N(F8)<=0),"",ROUND(F8*INDEX('Coëfficiënten'!$A$7:$AB$1006,MATCH(F8,INDEX('Coëfficiënten'!$A$7:$AB$1006,0,$AB8),1),$AB8+1),1)) | Q8: =IF(OR($AB8="",N(G8)<=0),"",ROUND(G8*INDEX('Coëfficiënten'!$A$7:$AB$1006,MATCH(G8,INDEX('Coëfficiënten'!$A$7:$AB$1006,0,$AB8),1),$AB8+1),1)) | R8: =IF(OR($AB8="",N(H8)<=0),"",ROUND(H8*INDEX('Coëfficiënten'!$A$7:$AB$1006,MATCH(H8,INDEX('Coëfficiënten'!$A$7:$AB$1006,0,$AB8),1),$AB8+1),1)) | S8: =IF(OR($AB8="",N(I8)<=0),"",ROUND(I8*INDEX('Coëfficiënten'!$A$7:$AB$1006,MATCH(I8,INDEX('Coëfficiënten'!$A$7:$AB$1006,0,$AB8),1),$AB8+1),1)) | T8: =IF(OR($AB8="",N(J8)<=0),"",ROUND(J8*INDEX('Coëfficiënten'!$A$7:$AB$1006,MATCH(J8,INDEX('Coëfficiënten'!$A$7:$AB$1006,0,$AB8),1),$AB8+1),1)) | U8: =IF(OR($AB8="",N(K8)<=0),"",ROUND(K8*INDEX('Coëfficiënten'!$A$7:$AB$1006,MATCH(K8,INDEX('Coëfficiënten'!$A$7:$AB$1006,0,$AB8),1),$AB8+1),1)) | V8: =IF(OR($AB8="",N(L8)<=0),"",ROUND(L8*INDEX('Coëfficiënten'!$A$7:$AB$1006,MATCH(L8,INDEX('Coëfficiënten'!$A$7:$AB$1006,0,$AB8),1),$AB8+1),1)) | ... X8: =IF(OR($AB8="",N(N8)<=0),"",ROUND(N8*INDEX('Coëfficiënten'!$A$7:$AB$1006,MATCH(N8,INDEX('Coëfficiënten'!$A$7:$AB$1006,0,$AB8),1),$AB8+1),1)) | Y8: =IF(OR($B8="",COUNT($O8:$X8)=0),"",IFERROR(LARGE($O8:$X8,1),0)*($AB$5>=1)+IFERROR(LARGE($O8:$X8,2),0)*($AB$5>=2)+IFERROR(LARGE($O8:$X8,3),0)*($AB$5>=3)+IFERROR(LARGE($O8:$X8,4),0)*($AB$5>=4)+IFERROR(LARGE($O8:$X8,5),0)*($AB$5>=5)+IFERROR(LARGE($O8:$X8,6),0)*($AB$5>=6)+IFERROR(LARGE($O8:$X8,7),0)*($AB$5>=7)+IFERROR(LARGE($O8:$X8,8),0)*($AB$5>=8)+IFERROR(LARGE($O8:$X8,9),0)*($AB$5>=9)+IFERROR(LARGE($O8:$X8,10),0)*($AB$5>=10)) | Z8: =IF(N($Y8)=0,"",$Y8/MIN($AB$5,COUNT($O8:$X8))) | AA8: =IF(N($Y8)=0,"",RANK($Y8,$Y$7:$Y$66)) | AB8: =IF(OR($C8="",$D8=""),"",IFERROR(MATCH($C8&"|"&VLOOKUP($D8,Uitleg!$B$23:$C$33,2,FALSE),'Coëfficiënten'!$A$5:$AB$5,0),"")) | AC8: =IF(N($Y8)=0,"",$Y8+(67-ROW())/1000000000)
A9: =ROW()-6 | O9: =IF(OR($AB9="",N(E9)<=0),"",ROUND(E9*INDEX('Coëfficiënten'!$A$7:$AB$1006,MATCH(E9,INDEX('Coëfficiënten'!$A$7:$AB$1006,0,$AB9),1),$AB9+1),1)) | P9: =IF(OR($AB9="",N(F9)<=0),"",ROUND(F9*INDEX('Coëfficiënten'!$A$7:$AB$1006,MATCH(F9,INDEX('Coëfficiënten'!$A$7:$AB$1006,0,$AB9),1),$AB9+1),1)) | Q9: =IF(OR($AB9="",N(G9)<=0),"",ROUND(G9*INDEX('Coëfficiënten'!$A$7:$AB$1006,MATCH(G9,INDEX('Coëfficiënten'!$A$7:$AB$1006,0,$AB9),1),$AB9+1),1)) | R9: =IF(OR($AB9="",N(H9)<=0),"",ROUND(H9*INDEX('Coëfficiënten'!$A$7:$AB$1006,MATCH(H9,INDEX('Coëfficiënten'!$A$7:$AB$1006,0,$AB9),1),$AB9+1),1)) | S9: =IF(OR($AB9="",N(I9)<=0),"",ROUND(I9*INDEX('Coëfficiënten'!$A$7:$AB$1006,MATCH(I9,INDEX('Coëfficiënten'!$A$7:$AB$1006,0,$AB9),1),$AB9+1),1)) | T9: =IF(OR($AB9="",N(J9)<=0),"",ROUND(J9*INDEX('Coëfficiënten'!$A$7:$AB$1006,MATCH(J9,INDEX('Coëfficiënten'!$A$7:$AB$1006,0,$AB9),1),$AB9+1),1)) | U9: =IF(OR($AB9="",N(K9)<=0),"",ROUND(K9*INDEX('Coëfficiënten'!$A$7:$AB$1006,MATCH(K9,INDEX('Coëfficiënten'!$A$7:$AB$1006,0,$AB9),1),$AB9+1),1)) | V9: =IF(OR($AB9="",N(L9)<=0),"",ROUND(L9*INDEX('Coëfficiënten'!$A$7:$AB$1006,MATCH(L9,INDEX('Coëfficiënten'!$A$7:$AB$1006,0,$AB9),1),$AB9+1),1)) | ... X9: =IF(OR($AB9="",N(N9)<=0),"",ROUND(N9*INDEX('Coëfficiënten'!$A$7:$AB$1006,MATCH(N9,INDEX('Coëfficiënten'!$A$7:$AB$1006,0,$AB9),1),$AB9+1),1)) | Y9: =IF(OR($B9="",COUNT($O9:$X9)=0),"",IFERROR(LARGE($O9:$X9,1),0)*($AB$5>=1)+IFERROR(LARGE($O9:$X9,2),0)*($AB$5>=2)+IFERROR(LARGE($O9:$X9,3),0)*($AB$5>=3)+IFERROR(LARGE($O9:$X9,4),0)*($AB$5>=4)+IFERROR(LARGE($O9:$X9,5),0)*($AB$5>=5)+IFERROR(LARGE($O9:$X9,6),0)*($AB$5>=6)+IFERROR(LARGE($O9:$X9,7),0)*($AB$5>=7)+IFERROR(LARGE($O9:$X9,8),0)*($AB$5>=8)+IFERROR(LARGE($O9:$X9,9),0)*($AB$5>=9)+IFERROR(LARGE($O9:$X9,10),0)*($AB$5>=10)) | Z9: =IF(N($Y9)=0,"",$Y9/MIN($AB$5,COUNT($O9:$X9))) | AA9: =IF(N($Y9)=0,"",RANK($Y9,$Y$7:$Y$66)) | AB9: =IF(OR($C9="",$D9=""),"",IFERROR(MATCH($C9&"|"&VLOOKUP($D9,Uitleg!$B$23:$C$33,2,FALSE),'Coëfficiënten'!$A$5:$AB$5,0),"")) | AC9: =IF(N($Y9)=0,"",$Y9+(67-ROW())/1000000000)
A10: =ROW()-6 | O10: =IF(OR($AB10="",N(E10)<=0),"",ROUND(E10*INDEX('Coëfficiënten'!$A$7:$AB$1006,MATCH(E10,INDEX('Coëfficiënten'!$A$7:$AB$1006,0,$AB10),1),$AB10+1),1)) | P10: =IF(OR($AB10="",N(F10)<=0),"",ROUND(F10*INDEX('Coëfficiënten'!$A$7:$AB$1006,MATCH(F10,INDEX('Coëfficiënten'!$A$7:$AB$1006,0,$AB10),1),$AB10+1),1)) | Q10: =IF(OR($AB10="",N(G10)<=0),"",ROUND(G10*INDEX('Coëfficiënten'!$A$7:$AB$1006,MATCH(G10,INDEX('Coëfficiënten'!$A$7:$AB$1006,0,$AB10),1),$AB10+1),1)) | R10: =IF(OR($AB10="",N(H10)<=0),"",ROUND(H10*INDEX('Coëfficiënten'!$A$7:$AB$1006,MATCH(H10,INDEX('Coëfficiënten'!$A$7:$AB$1006,0,$AB10),1),$AB10+1),1)) | S10: =IF(OR($AB10="",N(I10)<=0),"",ROUND(I10*INDEX('Coëfficiënten'!$A$7:$AB$1006,MATCH(I10,INDEX('Coëfficiënten'!$A$7:$AB$1006,0,$AB10),1),$AB10+1),1)) | T10: =IF(OR($AB10="",N(J10)<=0),"",ROUND(J10*INDEX('Coëfficiënten'!$A$7:$AB$1006,MATCH(J10,INDEX('Coëfficiënten'!$A$7:$AB$1006,0,$AB10),1),$AB10+1),1)) | U10: =IF(OR($AB10="",N(K10)<=0),"",ROUND(K10*INDEX('Coëfficiënten'!$A$7:$AB$1006,MATCH(K10,INDEX('Coëfficiënten'!$A$7:$AB$1006,0,$AB10),1),$AB10+1),1)) | V10: =IF(OR($AB10="",N(L10)<=0),"",ROUND(L10*INDEX('Coëfficiënten'!$A$7:$AB$1006,MATCH(L10,INDEX('Coëfficiënten'!$A$7:$AB$1006,0,$AB10),1),$AB10+1),1)) | ... X10: =IF(OR($AB10="",N(N10)<=0),"",ROUND(N10*INDEX('Coëfficiënten'!$A$7:$AB$1006,MATCH(N10,INDEX('Coëfficiënten'!$A$7:$AB$1006,0,$AB10),1),$AB10+1),1)) | Y10: =IF(OR($B10="",COUNT($O10:$X10)=0),"",IFERROR(LARGE($O10:$X10,1),0)*($AB$5>=1)+IFERROR(LARGE($O10:$X10,2),0)*($AB$5>=2)+IFERROR(LARGE($O10:$X10,3),0)*($AB$5>=3)+IFERROR(LARGE($O10:$X10,4),0)*($AB$5>=4)+IFERROR(LARGE($O10:$X10,5),0)*($AB$5>=5)+IFERROR(LARGE($O10:$X10,6),0)*($AB$5>=6)+IFERROR(LARGE($O10:$X10,7),0)*($AB$5>=7)+IFERROR(LARGE($O10:$X10,8),0)*($AB$5>=8)+IFERROR(LARGE($O10:$X10,9),0)*($AB$5>=9)+IFERROR(LARGE($O10:$X10,10),0)*($AB$5>=10)) | Z10: =IF(N($Y10)=0,"",$Y10/MIN($AB$5,COUNT($O10:$X10))) | AA10: =IF(N($Y10)=0,"",RANK($Y10,$Y$7:$Y$66)) | AB10: =IF(OR($C10="",$D10=""),"",IFERROR(MATCH($C10&"|"&VLOOKUP($D10,Uitleg!$B$23:$C$33,2,FALSE),'Coëfficiënten'!$A$5:$AB$5,0),"")) | AC10: =IF(N($Y10)=0,"",$Y10+(67-ROW())/1000000000)
A11: =ROW()-6 | O11: =IF(OR($AB11="",N(E11)<=0),"",ROUND(E11*INDEX('Coëfficiënten'!$A$7:$AB$1006,MATCH(E11,INDEX('Coëfficiënten'!$A$7:$AB$1006,0,$AB11),1),$AB11+1),1)) | P11: =IF(OR($AB11="",N(F11)<=0),"",ROUND(F11*INDEX('Coëfficiënten'!$A$7:$AB$1006,MATCH(F11,INDEX('Coëfficiënten'!$A$7:$AB$1006,0,$AB11),1),$AB11+1),1)) | Q11: =IF(OR($AB11="",N(G11)<=0),"",ROUND(G11*INDEX('Coëfficiënten'!$A$7:$AB$1006,MATCH(G11,INDEX('Coëfficiënten'!$A$7:$AB$1006,0,$AB11),1),$AB11+1),1)) | R11: =IF(OR($AB11="",N(H11)<=0),"",ROUND(H11*INDEX('Coëfficiënten'!$A$7:$AB$1006,MATCH(H11,INDEX('Coëfficiënten'!$A$7:$AB$1006,0,$AB11),1),$AB11+1),1)) | S11: =IF(OR($AB11="",N(I11)<=0),"",ROUND(I11*INDEX('Coëfficiënten'!$A$7:$AB$1006,MATCH(I11,INDEX('Coëfficiënten'!$A$7:$AB$1006,0,$AB11),1),$AB11+1),1)) | T11: =IF(OR($AB11="",N(J11)<=0),"",ROUND(J11*INDEX('Coëfficiënten'!$A$7:$AB$1006,MATCH(J11,INDEX('Coëfficiënten'!$A$7:$AB$1006,0,$AB11),1),$AB11+1),1)) | U11: =IF(OR($AB11="",N(K11)<=0),"",ROUND(K11*INDEX('Coëfficiënten'!$A$7:$AB$1006,MATCH(K11,INDEX('Coëfficiënten'!$A$7:$AB$1006,0,$AB11),1),$AB11+1),1)) | V11: =IF(OR($AB11="",N(L11)<=0),"",ROUND(L11*INDEX('Coëfficiënten'!$A$7:$AB$1006,MATCH(L11,INDEX('Coëfficiënten'!$A$7:$AB$1006,0,$AB11),1),$AB11+1),1)) | ... X11: =IF(OR($AB11="",N(N11)<=0),"",ROUND(N11*INDEX('Coëfficiënten'!$A$7:$AB$1006,MATCH(N11,INDEX('Coëfficiënten'!$A$7:$AB$1006,0,$AB11),1),$AB11+1),1)) | Y11: =IF(OR($B11="",COUNT($O11:$X11)=0),"",IFERROR(LARGE($O11:$X11,1),0)*($AB$5>=1)+IFERROR(LARGE($O11:$X11,2),0)*($AB$5>=2)+IFERROR(LARGE($O11:$X11,3),0)*($AB$5>=3)+IFERROR(LARGE($O11:$X11,4),0)*($AB$5>=4)+IFERROR(LARGE($O11:$X11,5),0)*($AB$5>=5)+IFERROR(LARGE($O11:$X11,6),0)*($AB$5>=6)+IFERROR(LARGE($O11:$X11,7),0)*($AB$5>=7)+IFERROR(LARGE($O11:$X11,8),0)*($AB$5>=8)+IFERROR(LARGE($O11:$X11,9),0)*($AB$5>=9)+IFERROR(LARGE($O11:$X11,10),0)*($AB$5>=10)) | Z11: =IF(N($Y11)=0,"",$Y11/MIN($AB$5,COUNT($O11:$X11))) | AA11: =IF(N($Y11)=0,"",RANK($Y11,$Y$7:$Y$66)) | AB11: =IF(OR($C11="",$D11=""),"",IFERROR(MATCH($C11&"|"&VLOOKUP($D11,Uitleg!$B$23:$C$33,2,FALSE),'Coëfficiënten'!$A$5:$AB$5,0),"")) | AC11: =IF(N($Y11)=0,"",$Y11+(67-ROW())/1000000000)
A12: =ROW()-6 | O12: =IF(OR($AB12="",N(E12)<=0),"",ROUND(E12*INDEX('Coëfficiënten'!$A$7:$AB$1006,MATCH(E12,INDEX('Coëfficiënten'!$A$7:$AB$1006,0,$AB12),1),$AB12+1),1)) | P12: =IF(OR($AB12="",N(F12)<=0),"",ROUND(F12*INDEX('Coëfficiënten'!$A$7:$AB$1006,MATCH(F12,INDEX('Coëfficiënten'!$A$7:$AB$1006,0,$AB12),1),$AB12+1),1)) | Q12: =IF(OR($AB12="",N(G12)<=0),"",ROUND(G12*INDEX('Coëfficiënten'!$A$7:$AB$1006,MATCH(G12,INDEX('Coëfficiënten'!$A$7:$AB$1006,0,$AB12),1),$AB12+1),1)) | R12: =IF(OR($AB12="",N(H12)<=0),"",ROUND(H12*INDEX('Coëfficiënten'!$A$7:$AB$1006,MATCH(H12,INDEX('Coëfficiënten'!$A$7:$AB$1006,0,$AB12),1),$AB12+1),1)) | S12: =IF(OR($AB12="",N(I12)<=0),"",ROUND(I12*INDEX('Coëfficiënten'!$A$7:$AB$1006,MATCH(I12,INDEX('Coëfficiënten'!$A$7:$AB$1006,0,$AB12),1),$AB12+1),1)) | T12: =IF(OR($AB12="",N(J12)<=0),"",ROUND(J12*INDEX('Coëfficiënten'!$A$7:$AB$1006,MATCH(J12,INDEX('Coëfficiënten'!$A$7:$AB$1006,0,$AB12),1),$AB12+1),1)) | U12: =IF(OR($AB12="",N(K12)<=0),"",ROUND(K12*INDEX('Coëfficiënten'!$A$7:$AB$1006,MATCH(K12,INDEX('Coëfficiënten'!$A$7:$AB$1006,0,$AB12),1),$AB12+1),1)) | V12: =IF(OR($AB12="",N(L12)<=0),"",ROUND(L12*INDEX('Coëfficiënten'!$A$7:$AB$1006,MATCH(L12,INDEX('Coëfficiënten'!$A$7:$AB$1006,0,$AB12),1),$AB12+1),1)) | ... X12: =IF(OR($AB12="",N(N12)<=0),"",ROUND(N12*INDEX('Coëfficiënten'!$A$7:$AB$1006,MATCH(N12,INDEX('Coëfficiënten'!$A$7:$AB$1006,0,$AB12),1),$AB12+1),1)) | Y12: =IF(OR($B12="",COUNT($O12:$X12)=0),"",IFERROR(LARGE($O12:$X12,1),0)*($AB$5>=1)+IFERROR(LARGE($O12:$X12,2),0)*($AB$5>=2)+IFERROR(LARGE($O12:$X12,3),0)*($AB$5>=3)+IFERROR(LARGE($O12:$X12,4),0)*($AB$5>=4)+IFERROR(LARGE($O12:$X12,5),0)*($AB$5>=5)+IFERROR(LARGE($O12:$X12,6),0)*($AB$5>=6)+IFERROR(LARGE($O12:$X12,7),0)*($AB$5>=7)+IFERROR(LARGE($O12:$X12,8),0)*($AB$5>=8)+IFERROR(LARGE($O12:$X12,9),0)*($AB$5>=9)+IFERROR(LARGE($O12:$X12,10),0)*($AB$5>=10)) | Z12: =IF(N($Y12)=0,"",$Y12/MIN($AB$5,COUNT($O12:$X12))) | AA12: =IF(N($Y12)=0,"",RANK($Y12,$Y$7:$Y$66)) | AB12: =IF(OR($C12="",$D12=""),"",IFERROR(MATCH($C12&"|"&VLOOKUP($D12,Uitleg!$B$23:$C$33,2,FALSE),'Coëfficiënten'!$A$5:$AB$5,0),"")) | AC12: =IF(N($Y12)=0,"",$Y12+(67-ROW())/1000000000)
A13: =ROW()-6 | O13: =IF(OR($AB13="",N(E13)<=0),"",ROUND(E13*INDEX('Coëfficiënten'!$A$7:$AB$1006,MATCH(E13,INDEX('Coëfficiënten'!$A$7:$AB$1006,0,$AB13),1),$AB13+1),1)) | P13: =IF(OR($AB13="",N(F13)<=0),"",ROUND(F13*INDEX('Coëfficiënten'!$A$7:$AB$1006,MATCH(F13,INDEX('Coëfficiënten'!$A$7:$AB$1006,0,$AB13),1),$AB13+1),1)) | Q13: =IF(OR($AB13="",N(G13)<=0),"",ROUND(G13*INDEX('Coëfficiënten'!$A$7:$AB$1006,MATCH(G13,INDEX('Coëfficiënten'!$A$7:$AB$1006,0,$AB13),1),$AB13+1),1)) | R13: =IF(OR($AB13="",N(H13)<=0),"",ROUND(H13*INDEX('Coëfficiënten'!$A$7:$AB$1006,MATCH(H13,INDEX('Coëfficiënten'!$A$7:$AB$1006,0,$AB13),1),$AB13+1),1)) | S13: =IF(OR($AB13="",N(I13)<=0),"",ROUND(I13*INDEX('Coëfficiënten'!$A$7:$AB$1006,MATCH(I13,INDEX('Coëfficiënten'!$A$7:$AB$1006,0,$AB13),1),$AB13+1),1)) | T13: =IF(OR($AB13="",N(J13)<=0),"",ROUND(J13*INDEX('Coëfficiënten'!$A$7:$AB$1006,MATCH(J13,INDEX('Coëfficiënten'!$A$7:$AB$1006,0,$AB13),1),$AB13+1),1)) | U13: =IF(OR($AB13="",N(K13)<=0),"",ROUND(K13*INDEX('Coëfficiënten'!$A$7:$AB$1006,MATCH(K13,INDEX('Coëfficiënten'!$A$7:$AB$1006,0,$AB13),1),$AB13+1),1)) | V13: =IF(OR($AB13="",N(L13)<=0),"",ROUND(L13*INDEX('Coëfficiënten'!$A$7:$AB$1006,MATCH(L13,INDEX('Coëfficiënten'!$A$7:$AB$1006,0,$AB13),1),$AB13+1),1)) | ... X13: =IF(OR($AB13="",N(N13)<=0),"",ROUND(N13*INDEX('Coëfficiënten'!$A$7:$AB$1006,MATCH(N13,INDEX('Coëfficiënten'!$A$7:$AB$1006,0,$AB13),1),$AB13+1),1)) | Y13: =IF(OR($B13="",COUNT($O13:$X13)=0),"",IFERROR(LARGE($O13:$X13,1),0)*($AB$5>=1)+IFERROR(LARGE($O13:$X13,2),0)*($AB$5>=2)+IFERROR(LARGE($O13:$X13,3),0)*($AB$5>=3)+IFERROR(LARGE($O13:$X13,4),0)*($AB$5>=4)+IFERROR(LARGE($O13:$X13,5),0)*($AB$5>=5)+IFERROR(LARGE($O13:$X13,6),0)*($AB$5>=6)+IFERROR(LARGE($O13:$X13,7),0)*($AB$5>=7)+IFERROR(LARGE($O13:$X13,8),0)*($AB$5>=8)+IFERROR(LARGE($O13:$X13,9),0)*($AB$5>=9)+IFERROR(LARGE($O13:$X13,10),0)*($AB$5>=10)) | Z13: =IF(N($Y13)=0,"",$Y13/MIN($AB$5,COUNT($O13:$X13))) | AA13: =IF(N($Y13)=0,"",RANK($Y13,$Y$7:$Y$66)) | AB13: =IF(OR($C13="",$D13=""),"",IFERROR(MATCH($C13&"|"&VLOOKUP($D13,Uitleg!$B$23:$C$33,2,FALSE),'Coëfficiënten'!$A$5:$AB$5,0),"")) | AC13: =IF(N($Y13)=0,"",$Y13+(67-ROW())/1000000000)
A14: =ROW()-6 | O14: =IF(OR($AB14="",N(E14)<=0),"",ROUND(E14*INDEX('Coëfficiënten'!$A$7:$AB$1006,MATCH(E14,INDEX('Coëfficiënten'!$A$7:$AB$1006,0,$AB14),1),$AB14+1),1)) | P14: =IF(OR($AB14="",N(F14)<=0),"",ROUND(F14*INDEX('Coëfficiënten'!$A$7:$AB$1006,MATCH(F14,INDEX('Coëfficiënten'!$A$7:$AB$1006,0,$AB14),1),$AB14+1),1)) | Q14: =IF(OR($AB14="",N(G14)<=0),"",ROUND(G14*INDEX('Coëfficiënten'!$A$7:$AB$1006,MATCH(G14,INDEX('Coëfficiënten'!$A$7:$AB$1006,0,$AB14),1),$AB14+1),1)) | R14: =IF(OR($AB14="",N(H14)<=0),"",ROUND(H14*INDEX('Coëfficiënten'!$A$7:$AB$1006,MATCH(H14,INDEX('Coëfficiënten'!$A$7:$AB$1006,0,$AB14),1),$AB14+1),1)) | S14: =IF(OR($AB14="",N(I14)<=0),"",ROUND(I14*INDEX('Coëfficiënten'!$A$7:$AB$1006,MATCH(I14,INDEX('Coëfficiënten'!$A$7:$AB$1006,0,$AB14),1),$AB14+1),1)) | T14: =IF(OR($AB14="",N(J14)<=0),"",ROUND(J14*INDEX('Coëfficiënten'!$A$7:$AB$1006,MATCH(J14,INDEX('Coëfficiënten'!$A$7:$AB$1006,0,$AB14),1),$AB14+1),1)) | U14: =IF(OR($AB14="",N(K14)<=0),"",ROUND(K14*INDEX('Coëfficiënten'!$A$7:$AB$1006,MATCH(K14,INDEX('Coëfficiënten'!$A$7:$AB$1006,0,$AB14),1),$AB14+1),1)) | V14: =IF(OR($AB14="",N(L14)<=0),"",ROUND(L14*INDEX('Coëfficiënten'!$A$7:$AB$1006,MATCH(L14,INDEX('Coëfficiënten'!$A$7:$AB$1006,0,$AB14),1),$AB14+1),1)) | ... X14: =IF(OR($AB14="",N(N14)<=0),"",ROUND(N14*INDEX('Coëfficiënten'!$A$7:$AB$1006,MATCH(N14,INDEX('Coëfficiënten'!$A$7:$AB$1006,0,$AB14),1),$AB14+1),1)) | Y14: =IF(OR($B14="",COUNT($O14:$X14)=0),"",IFERROR(LARGE($O14:$X14,1),0)*($AB$5>=1)+IFERROR(LARGE($O14:$X14,2),0)*($AB$5>=2)+IFERROR(LARGE($O14:$X14,3),0)*($AB$5>=3)+IFERROR(LARGE($O14:$X14,4),0)*($AB$5>=4)+IFERROR(LARGE($O14:$X14,5),0)*($AB$5>=5)+IFERROR(LARGE($O14:$X14,6),0)*($AB$5>=6)+IFERROR(LARGE($O14:$X14,7),0)*($AB$5>=7)+IFERROR(LARGE($O14:$X14,8),0)*($AB$5>=8)+IFERROR(LARGE($O14:$X14,9),0)*($AB$5>=9)+IFERROR(LARGE($O14:$X14,10),0)*($AB$5>=10)) | Z14: =IF(N($Y14)=0,"",$Y14/MIN($AB$5,COUNT($O14:$X14))) | AA14: =IF(N($Y14)=0,"",RANK($Y14,$Y$7:$Y$66)) | AB14: =IF(OR($C14="",$D14=""),"",IFERROR(MATCH($C14&"|"&VLOOKUP($D14,Uitleg!$B$23:$C$33,2,FALSE),'Coëfficiënten'!$A$5:$AB$5,0),"")) | AC14: =IF(N($Y14)=0,"",$Y14+(67-ROW())/1000000000)
A15: =ROW()-6 | O15: =IF(OR($AB15="",N(E15)<=0),"",ROUND(E15*INDEX('Coëfficiënten'!$A$7:$AB$1006,MATCH(E15,INDEX('Coëfficiënten'!$A$7:$AB$1006,0,$AB15),1),$AB15+1),1)) | P15: =IF(OR($AB15="",N(F15)<=0),"",ROUND(F15*INDEX('Coëfficiënten'!$A$7:$AB$1006,MATCH(F15,INDEX('Coëfficiënten'!$A$7:$AB$1006,0,$AB15),1),$AB15+1),1)) | Q15: =IF(OR($AB15="",N(G15)<=0),"",ROUND(G15*INDEX('Coëfficiënten'!$A$7:$AB$1006,MATCH(G15,INDEX('Coëfficiënten'!$A$7:$AB$1006,0,$AB15),1),$AB15+1),1)) | R15: =IF(OR($AB15="",N(H15)<=0),"",ROUND(H15*INDEX('Coëfficiënten'!$A$7:$AB$1006,MATCH(H15,INDEX('Coëfficiënten'!$A$7:$AB$1006,0,$AB15),1),$AB15+1),1)) | S15: =IF(OR($AB15="",N(I15)<=0),"",ROUND(I15*INDEX('Coëfficiënten'!$A$7:$AB$1006,MATCH(I15,INDEX('Coëfficiënten'!$A$7:$AB$1006,0,$AB15),1),$AB15+1),1)) | T15: =IF(OR($AB15="",N(J15)<=0),"",ROUND(J15*INDEX('Coëfficiënten'!$A$7:$AB$1006,MATCH(J15,INDEX('Coëfficiënten'!$A$7:$AB$1006,0,$AB15),1),$AB15+1),1)) | U15: =IF(OR($AB15="",N(K15)<=0),"",ROUND(K15*INDEX('Coëfficiënten'!$A$7:$AB$1006,MATCH(K15,INDEX('Coëfficiënten'!$A$7:$AB$1006,0,$AB15),1),$AB15+1),1)) | V15: =IF(OR($AB15="",N(L15)<=0),"",ROUND(L15*INDEX('Coëfficiënten'!$A$7:$AB$1006,MATCH(L15,INDEX('Coëfficiënten'!$A$7:$AB$1006,0,$AB15),1),$AB15+1),1)) | ... X15: =IF(OR($AB15="",N(N15)<=0),"",ROUND(N15*INDEX('Coëfficiënten'!$A$7:$AB$1006,MATCH(N15,INDEX('Coëfficiënten'!$A$7:$AB$1006,0,$AB15),1),$AB15+1),1)) | Y15: =IF(OR($B15="",COUNT($O15:$X15)=0),"",IFERROR(LARGE($O15:$X15,1),0)*($AB$5>=1)+IFERROR(LARGE($O15:$X15,2),0)*($AB$5>=2)+IFERROR(LARGE($O15:$X15,3),0)*($AB$5>=3)+IFERROR(LARGE($O15:$X15,4),0)*($AB$5>=4)+IFERROR(LARGE($O15:$X15,5),0)*($AB$5>=5)+IFERROR(LARGE($O15:$X15,6),0)*($AB$5>=6)+IFERROR(LARGE($O15:$X15,7),0)*($AB$5>=7)+IFERROR(LARGE($O15:$X15,8),0)*($AB$5>=8)+IFERROR(LARGE($O15:$X15,9),0)*($AB$5>=9)+IFERROR(LARGE($O15:$X15,10),0)*($AB$5>=10)) | Z15: =IF(N($Y15)=0,"",$Y15/MIN($AB$5,COUNT($O15:$X15))) | AA15: =IF(N($Y15)=0,"",RANK($Y15,$Y$7:$Y$66)) | AB15: =IF(OR($C15="",$D15=""),"",IFERROR(MATCH($C15&"|"&VLOOKUP($D15,Uitleg!$B$23:$C$33,2,FALSE),'Coëfficiënten'!$A$5:$AB$5,0),"")) | AC15: =IF(N($Y15)=0,"",$Y15+(67-ROW())/1000000000)
A16: =ROW()-6 | O16: =IF(OR($AB16="",N(E16)<=0),"",ROUND(E16*INDEX('Coëfficiënten'!$A$7:$AB$1006,MATCH(E16,INDEX('Coëfficiënten'!$A$7:$AB$1006,0,$AB16),1),$AB16+1),1)) | P16: =IF(OR($AB16="",N(F16)<=0),"",ROUND(F16*INDEX('Coëfficiënten'!$A$7:$AB$1006,MATCH(F16,INDEX('Coëfficiënten'!$A$7:$AB$1006,0,$AB16),1),$AB16+1),1)) | Q16: =IF(OR($AB16="",N(G16)<=0),"",ROUND(G16*INDEX('Coëfficiënten'!$A$7:$AB$1006,MATCH(G16,INDEX('Coëfficiënten'!$A$7:$AB$1006,0,$AB16),1),$AB16+1),1)) | R16: =IF(OR($AB16="",N(H16)<=0),"",ROUND(H16*INDEX('Coëfficiënten'!$A$7:$AB$1006,MATCH(H16,INDEX('Coëfficiënten'!$A$7:$AB$1006,0,$AB16),1),$AB16+1),1)) | S16: =IF(OR($AB16="",N(I16)<=0),"",ROUND(I16*INDEX('Coëfficiënten'!$A$7:$AB$1006,MATCH(I16,INDEX('Coëfficiënten'!$A$7:$AB$1006,0,$AB16),1),$AB16+1),1)) | T16: =IF(OR($AB16="",N(J16)<=0),"",ROUND(J16*INDEX('Coëfficiënten'!$A$7:$AB$1006,MATCH(J16,INDEX('Coëfficiënten'!$A$7:$AB$1006,0,$AB16),1),$AB16+1),1)) | U16: =IF(OR($AB16="",N(K16)<=0),"",ROUND(K16*INDEX('Coëfficiënten'!$A$7:$AB$1006,MATCH(K16,INDEX('Coëfficiënten'!$A$7:$AB$1006,0,$AB16),1),$AB16+1),1)) | V16: =IF(OR($AB16="",N(L16)<=0),"",ROUND(L16*INDEX('Coëfficiënten'!$A$7:$AB$1006,MATCH(L16,INDEX('Coëfficiënten'!$A$7:$AB$1006,0,$AB16),1),$AB16+1),1)) | ... X16: =IF(OR($AB16="",N(N16)<=0),"",ROUND(N16*INDEX('Coëfficiënten'!$A$7:$AB$1006,MATCH(N16,INDEX('Coëfficiënten'!$A$7:$AB$1006,0,$AB16),1),$AB16+1),1)) | Y16: =IF(OR($B16="",COUNT($O16:$X16)=0),"",IFERROR(LARGE($O16:$X16,1),0)*($AB$5>=1)+IFERROR(LARGE($O16:$X16,2),0)*($AB$5>=2)+IFERROR(LARGE($O16:$X16,3),0)*($AB$5>=3)+IFERROR(LARGE($O16:$X16,4),0)*($AB$5>=4)+IFERROR(LARGE($O16:$X16,5),0)*($AB$5>=5)+IFERROR(LARGE($O16:$X16,6),0)*($AB$5>=6)+IFERROR(LARGE($O16:$X16,7),0)*($AB$5>=7)+IFERROR(LARGE($O16:$X16,8),0)*($AB$5>=8)+IFERROR(LARGE($O16:$X16,9),0)*($AB$5>=9)+IFERROR(LARGE($O16:$X16,10),0)*($AB$5>=10)) | Z16: =IF(N($Y16)=0,"",$Y16/MIN($AB$5,COUNT($O16:$X16))) | AA16: =IF(N($Y16)=0,"",RANK($Y16,$Y$7:$Y$66)) | AB16: =IF(OR($C16="",$D16=""),"",IFERROR(MATCH($C16&"|"&VLOOKUP($D16,Uitleg!$B$23:$C$33,2,FALSE),'Coëfficiënten'!$A$5:$AB$5,0),"")) | AC16: =IF(N($Y16)=0,"",$Y16+(67-ROW())/1000000000)
A17: =ROW()-6 | O17: =IF(OR($AB17="",N(E17)<=0),"",ROUND(E17*INDEX('Coëfficiënten'!$A$7:$AB$1006,MATCH(E17,INDEX('Coëfficiënten'!$A$7:$AB$1006,0,$AB17),1),$AB17+1),1)) | P17: =IF(OR($AB17="",N(F17)<=0),"",ROUND(F17*INDEX('Coëfficiënten'!$A$7:$AB$1006,MATCH(F17,INDEX('Coëfficiënten'!$A$7:$AB$1006,0,$AB17),1),$AB17+1),1)) | Q17: =IF(OR($AB17="",N(G17)<=0),"",ROUND(G17*INDEX('Coëfficiënten'!$A$7:$AB$1006,MATCH(G17,INDEX('Coëfficiënten'!$A$7:$AB$1006,0,$AB17),1),$AB17+1),1)) | R17: =IF(OR($AB17="",N(H17)<=0),"",ROUND(H17*INDEX('Coëfficiënten'!$A$7:$AB$1006,MATCH(H17,INDEX('Coëfficiënten'!$A$7:$AB$1006,0,$AB17),1),$AB17+1),1)) | S17: =IF(OR($AB17="",N(I17)<=0),"",ROUND(I17*INDEX('Coëfficiënten'!$A$7:$AB$1006,MATCH(I17,INDEX('Coëfficiënten'!$A$7:$AB$1006,0,$AB17),1),$AB17+1),1)) | T17: =IF(OR($AB17="",N(J17)<=0),"",ROUND(J17*INDEX('Coëfficiënten'!$A$7:$AB$1006,MATCH(J17,INDEX('Coëfficiënten'!$A$7:$AB$1006,0,$AB17),1),$AB17+1),1)) | U17: =IF(OR($AB17="",N(K17)<=0),"",ROUND(K17*INDEX('Coëfficiënten'!$A$7:$AB$1006,MATCH(K17,INDEX('Coëfficiënten'!$A$7:$AB$1006,0,$AB17),1),$AB17+1),1)) | V17: =IF(OR($AB17="",N(L17)<=0),"",ROUND(L17*INDEX('Coëfficiënten'!$A$7:$AB$1006,MATCH(L17,INDEX('Coëfficiënten'!$A$7:$AB$1006,0,$AB17),1),$AB17+1),1)) | ... X17: =IF(OR($AB17="",N(N17)<=0),"",ROUND(N17*INDEX('Coëfficiënten'!$A$7:$AB$1006,MATCH(N17,INDEX('Coëfficiënten'!$A$7:$AB$1006,0,$AB17),1),$AB17+1),1)) | Y17: =IF(OR($B17="",COUNT($O17:$X17)=0),"",IFERROR(LARGE($O17:$X17,1),0)*($AB$5>=1)+IFERROR(LARGE($O17:$X17,2),0)*($AB$5>=2)+IFERROR(LARGE($O17:$X17,3),0)*($AB$5>=3)+IFERROR(LARGE($O17:$X17,4),0)*($AB$5>=4)+IFERROR(LARGE($O17:$X17,5),0)*($AB$5>=5)+IFERROR(LARGE($O17:$X17,6),0)*($AB$5>=6)+IFERROR(LARGE($O17:$X17,7),0)*($AB$5>=7)+IFERROR(LARGE($O17:$X17,8),0)*($AB$5>=8)+IFERROR(LARGE($O17:$X17,9),0)*($AB$5>=9)+IFERROR(LARGE($O17:$X17,10),0)*($AB$5>=10)) | Z17: =IF(N($Y17)=0,"",$Y17/MIN($AB$5,COUNT($O17:$X17))) | AA17: =IF(N($Y17)=0,"",RANK($Y17,$Y$7:$Y$66)) | AB17: =IF(OR($C17="",$D17=""),"",IFERROR(MATCH($C17&"|"&VLOOKUP($D17,Uitleg!$B$23:$C$33,2,FALSE),'Coëfficiënten'!$A$5:$AB$5,0),"")) | AC17: =IF(N($Y17)=0,"",$Y17+(67-ROW())/1000000000)
A18: =ROW()-6 | O18: =IF(OR($AB18="",N(E18)<=0),"",ROUND(E18*INDEX('Coëfficiënten'!$A$7:$AB$1006,MATCH(E18,INDEX('Coëfficiënten'!$A$7:$AB$1006,0,$AB18),1),$AB18+1),1)) | P18: =IF(OR($AB18="",N(F18)<=0),"",ROUND(F18*INDEX('Coëfficiënten'!$A$7:$AB$1006,MATCH(F18,INDEX('Coëfficiënten'!$A$7:$AB$1006,0,$AB18),1),$AB18+1),1)) | Q18: =IF(OR($AB18="",N(G18)<=0),"",ROUND(G18*INDEX('Coëfficiënten'!$A$7:$AB$1006,MATCH(G18,INDEX('Coëfficiënten'!$A$7:$AB$1006,0,$AB18),1),$AB18+1),1)) | R18: =IF(OR($AB18="",N(H18)<=0),"",ROUND(H18*INDEX('Coëfficiënten'!$A$7:$AB$1006,MATCH(H18,INDEX('Coëfficiënten'!$A$7:$AB$1006,0,$AB18),1),$AB18+1),1)) | S18: =IF(OR($AB18="",N(I18)<=0),"",ROUND(I18*INDEX('Coëfficiënten'!$A$7:$AB$1006,MATCH(I18,INDEX('Coëfficiënten'!$A$7:$AB$1006,0,$AB18),1),$AB18+1),1)) | T18: =IF(OR($AB18="",N(J18)<=0),"",ROUND(J18*INDEX('Coëfficiënten'!$A$7:$AB$1006,MATCH(J18,INDEX('Coëfficiënten'!$A$7:$AB$1006,0,$AB18),1),$AB18+1),1)) | U18: =IF(OR($AB18="",N(K18)<=0),"",ROUND(K18*INDEX('Coëfficiënten'!$A$7:$AB$1006,MATCH(K18,INDEX('Coëfficiënten'!$A$7:$AB$1006,0,$AB18),1),$AB18+1),1)) | V18: =IF(OR($AB18="",N(L18)<=0),"",ROUND(L18*INDEX('Coëfficiënten'!$A$7:$AB$1006,MATCH(L18,INDEX('Coëfficiënten'!$A$7:$AB$1006,0,$AB18),1),$AB18+1),1)) | ... X18: =IF(OR($AB18="",N(N18)<=0),"",ROUND(N18*INDEX('Coëfficiënten'!$A$7:$AB$1006,MATCH(N18,INDEX('Coëfficiënten'!$A$7:$AB$1006,0,$AB18),1),$AB18+1),1)) | Y18: =IF(OR($B18="",COUNT($O18:$X18)=0),"",IFERROR(LARGE($O18:$X18,1),0)*($AB$5>=1)+IFERROR(LARGE($O18:$X18,2),0)*($AB$5>=2)+IFERROR(LARGE($O18:$X18,3),0)*($AB$5>=3)+IFERROR(LARGE($O18:$X18,4),0)*($AB$5>=4)+IFERROR(LARGE($O18:$X18,5),0)*($AB$5>=5)+IFERROR(LARGE($O18:$X18,6),0)*($AB$5>=6)+IFERROR(LARGE($O18:$X18,7),0)*($AB$5>=7)+IFERROR(LARGE($O18:$X18,8),0)*($AB$5>=8)+IFERROR(LARGE($O18:$X18,9),0)*($AB$5>=9)+IFERROR(LARGE($O18:$X18,10),0)*($AB$5>=10)) | Z18: =IF(N($Y18)=0,"",$Y18/MIN($AB$5,COUNT($O18:$X18))) | AA18: =IF(N($Y18)=0,"",RANK($Y18,$Y$7:$Y$66)) | AB18: =IF(OR($C18="",$D18=""),"",IFERROR(MATCH($C18&"|"&VLOOKUP($D18,Uitleg!$B$23:$C$33,2,FALSE),'Coëfficiënten'!$A$5:$AB$5,0),"")) | AC18: =IF(N($Y18)=0,"",$Y18+(67-ROW())/1000000000)
A19: =ROW()-6 | O19: =IF(OR($AB19="",N(E19)<=0),"",ROUND(E19*INDEX('Coëfficiënten'!$A$7:$AB$1006,MATCH(E19,INDEX('Coëfficiënten'!$A$7:$AB$1006,0,$AB19),1),$AB19+1),1)) | P19: =IF(OR($AB19="",N(F19)<=0),"",ROUND(F19*INDEX('Coëfficiënten'!$A$7:$AB$1006,MATCH(F19,INDEX('Coëfficiënten'!$A$7:$AB$1006,0,$AB19),1),$AB19+1),1)) | Q19: =IF(OR($AB19="",N(G19)<=0),"",ROUND(G19*INDEX('Coëfficiënten'!$A$7:$AB$1006,MATCH(G19,INDEX('Coëfficiënten'!$A$7:$AB$1006,0,$AB19),1),$AB19+1),1)) | R19: =IF(OR($AB19="",N(H19)<=0),"",ROUND(H19*INDEX('Coëfficiënten'!$A$7:$AB$1006,MATCH(H19,INDEX('Coëfficiënten'!$A$7:$AB$1006,0,$AB19),1),$AB19+1),1)) | S19: =IF(OR($AB19="",N(I19)<=0),"",ROUND(I19*INDEX('Coëfficiënten'!$A$7:$AB$1006,MATCH(I19,INDEX('Coëfficiënten'!$A$7:$AB$1006,0,$AB19),1),$AB19+1),1)) | T19: =IF(OR($AB19="",N(J19)<=0),"",ROUND(J19*INDEX('Coëfficiënten'!$A$7:$AB$1006,MATCH(J19,INDEX('Coëfficiënten'!$A$7:$AB$1006,0,$AB19),1),$AB19+1),1)) | U19: =IF(OR($AB19="",N(K19)<=0),"",ROUND(K19*INDEX('Coëfficiënten'!$A$7:$AB$1006,MATCH(K19,INDEX('Coëfficiënten'!$A$7:$AB$1006,0,$AB19),1),$AB19+1),1)) | V19: =IF(OR($AB19="",N(L19)<=0),"",ROUND(L19*INDEX('Coëfficiënten'!$A$7:$AB$1006,MATCH(L19,INDEX('Coëfficiënten'!$A$7:$AB$1006,0,$AB19),1),$AB19+1),1)) | ... X19: =IF(OR($AB19="",N(N19)<=0),"",ROUND(N19*INDEX('Coëfficiënten'!$A$7:$AB$1006,MATCH(N19,INDEX('Coëfficiënten'!$A$7:$AB$1006,0,$AB19),1),$AB19+1),1)) | Y19: =IF(OR($B19="",COUNT($O19:$X19)=0),"",IFERROR(LARGE($O19:$X19,1),0)*($AB$5>=1)+IFERROR(LARGE($O19:$X19,2),0)*($AB$5>=2)+IFERROR(LARGE($O19:$X19,3),0)*($AB$5>=3)+IFERROR(LARGE($O19:$X19,4),0)*($AB$5>=4)+IFERROR(LARGE($O19:$X19,5),0)*($AB$5>=5)+IFERROR(LARGE($O19:$X19,6),0)*($AB$5>=6)+IFERROR(LARGE($O19:$X19,7),0)*($AB$5>=7)+IFERROR(LARGE($O19:$X19,8),0)*($AB$5>=8)+IFERROR(LARGE($O19:$X19,9),0)*($AB$5>=9)+IFERROR(LARGE($O19:$X19,10),0)*($AB$5>=10)) | Z19: =IF(N($Y19)=0,"",$Y19/MIN($AB$5,COUNT($O19:$X19))) | AA19: =IF(N($Y19)=0,"",RANK($Y19,$Y$7:$Y$66)) | AB19: =IF(OR($C19="",$D19=""),"",IFERROR(MATCH($C19&"|"&VLOOKUP($D19,Uitleg!$B$23:$C$33,2,FALSE),'Coëfficiënten'!$A$5:$AB$5,0),"")) | AC19: =IF(N($Y19)=0,"",$Y19+(67-ROW())/1000000000)
... A66: =ROW()-6 | O66: =IF(OR($AB66="",N(E66)<=0),"",ROUND(E66*INDEX('Coëfficiënten'!$A$7:$AB$1006,MATCH(E66,INDEX('Coëfficiënten'!$A$7:$AB$1006,0,$AB66),1),$AB66+1),1)) | P66: =IF(OR($AB66="",N(F66)<=0),"",ROUND(F66*INDEX('Coëfficiënten'!$A$7:$AB$1006,MATCH(F66,INDEX('Coëfficiënten'!$A$7:$AB$1006,0,$AB66),1),$AB66+1),1)) | Q66: =IF(OR($AB66="",N(G66)<=0),"",ROUND(G66*INDEX('Coëfficiënten'!$A$7:$AB$1006,MATCH(G66,INDEX('Coëfficiënten'!$A$7:$AB$1006,0,$AB66),1),$AB66+1),1)) | R66: =IF(OR($AB66="",N(H66)<=0),"",ROUND(H66*INDEX('Coëfficiënten'!$A$7:$AB$1006,MATCH(H66,INDEX('Coëfficiënten'!$A$7:$AB$1006,0,$AB66),1),$AB66+1),1)) | S66: =IF(OR($AB66="",N(I66)<=0),"",ROUND(I66*INDEX('Coëfficiënten'!$A$7:$AB$1006,MATCH(I66,INDEX('Coëfficiënten'!$A$7:$AB$1006,0,$AB66),1),$AB66+1),1)) | T66: =IF(OR($AB66="",N(J66)<=0),"",ROUND(J66*INDEX('Coëfficiënten'!$A$7:$AB$1006,MATCH(J66,INDEX('Coëfficiënten'!$A$7:$AB$1006,0,$AB66),1),$AB66+1),1)) | U66: =IF(OR($AB66="",N(K66)<=0),"",ROUND(K66*INDEX('Coëfficiënten'!$A$7:$AB$1006,MATCH(K66,INDEX('Coëfficiënten'!$A$7:$AB$1006,0,$AB66),1),$AB66+1),1)) | V66: =IF(OR($AB66="",N(L66)<=0),"",ROUND(L66*INDEX('Coëfficiënten'!$A$7:$AB$1006,MATCH(L66,INDEX('Coëfficiënten'!$A$7:$AB$1006,0,$AB66),1),$AB66+1),1)) | ... X66: =IF(OR($AB66="",N(N66)<=0),"",ROUND(N66*INDEX('Coëfficiënten'!$A$7:$AB$1006,MATCH(N66,INDEX('Coëfficiënten'!$A$7:$AB$1006,0,$AB66),1),$AB66+1),1)) | Y66: =IF(OR($B66="",COUNT($O66:$X66)=0),"",IFERROR(LARGE($O66:$X66,1),0)*($AB$5>=1)+IFERROR(LARGE($O66:$X66,2),0)*($AB$5>=2)+IFERROR(LARGE($O66:$X66,3),0)*($AB$5>=3)+IFERROR(LARGE($O66:$X66,4),0)*($AB$5>=4)+IFERROR(LARGE($O66:$X66,5),0)*($AB$5>=5)+IFERROR(LARGE($O66:$X66,6),0)*($AB$5>=6)+IFERROR(LARGE($O66:$X66,7),0)*($AB$5>=7)+IFERROR(LARGE($O66:$X66,8),0)*($AB$5>=8)+IFERROR(LARGE($O66:$X66,9),0)*($AB$5>=9)+IFERROR(LARGE($O66:$X66,10),0)*($AB$5>=10)) | Z66: =IF(N($Y66)=0,"",$Y66/MIN($AB$5,COUNT($O66:$X66))) | AA66: =IF(N($Y66)=0,"",RANK($Y66,$Y$7:$Y$66)) | AB66: =IF(OR($C66="",$D66=""),"",IFERROR(MATCH($C66&"|"&VLOOKUP($D66,Uitleg!$B$23:$C$33,2,FALSE),'Coëfficiënten'!$A$5:$AB$5,0),"")) | AC66: =IF(N($Y66)=0,"",$Y66+(67-ROW())/1000000000)

Sheet Klassement
A2: ="Luchtdruk Clubklassement "&Uitleg!$C$7
R5: =Uitleg!$C$8
A6: Pl. | B6: Naam | C6: Disc. | D6: Cat. | F6: W1 | G6: W2 | H6: W3 | I6: W4 | J6: W5 | K6: W6 | L6: W7 | M6: W8 | N6: W9 | O6: W10 | P6: ="Beste "&Uitleg!$C$8 | Q6: Gemiddelde | R6: sorteer | S6: rij
A7: =IF($S7="","",INDEX(Resultaten!$AA$7:$AA$66,$S7)) | B7: =IF($S7="","",INDEX(Resultaten!$B$7:$B$66,$S7)) | C7: =IF($S7="","",INDEX(Resultaten!$C$7:$C$66,$S7)) | D7: =IF($S7="","",INDEX(Resultaten!$D$7:$D$66,$S7)) | E7: =IF($S7="","","Geschoten") | F7: =IF($S7="","",IF(INDEX(Resultaten!$E$7:$N$66,$S7,1)="","",INDEX(Resultaten!$E$7:$N$66,$S7,1))) | G7: =IF($S7="","",IF(INDEX(Resultaten!$E$7:$N$66,$S7,2)="","",INDEX(Resultaten!$E$7:$N$66,$S7,2))) | H7: =IF($S7="","",IF(INDEX(Resultaten!$E$7:$N$66,$S7,3)="","",INDEX(Resultaten!$E$7:$N$66,$S7,3))) | I7: =IF($S7="","",IF(INDEX(Resultaten!$E$7:$N$66,$S7,4)="","",INDEX(Resultaten!$E$7:$N$66,$S7,4))) | J7: =IF($S7="","",IF(INDEX(Resultaten!$E$7:$N$66,$S7,5)="","",INDEX(Resultaten!$E$7:$N$66,$S7,5))) | K7: =IF($S7="","",IF(INDEX(Resultaten!$E$7:$N$66,$S7,6)="","",INDEX(Resultaten!$E$7:$N$66,$S7,6))) | L7: =IF($S7="","",IF(INDEX(Resultaten!$E$7:$N$66,$S7,7)="","",INDEX(Resultaten!$E$7:$N$66,$S7,7))) | M7: =IF($S7="","",IF(INDEX(Resultaten!$E$7:$N$66,$S7,8)="","",INDEX(Resultaten!$E$7:$N$66,$S7,8))) | N7: =IF($S7="","",IF(INDEX(Resultaten!$E$7:$N$66,$S7,9)="","",INDEX(Resultaten!$E$7:$N$66,$S7,9))) | O7: =IF($S7="","",IF(INDEX(Resultaten!$E$7:$N$66,$S7,10)="","",INDEX(Resultaten!$E$7:$N$66,$S7,10))) | P7: =IF(OR($S7="",COUNT($F7:$O7)=0),"",ROUND(IFERROR(LARGE($F7:$O7,1),0)*($R$5>=1)+IFERROR(LARGE($F7:$O7,2),0)*($R$5>=2)+IFERROR(LARGE($F7:$O7,3),0)*($R$5>=3)+IFERROR(LARGE($F7:$O7,4),0)*($R$5>=4)+IFERROR(LARGE($F7:$O7,5),0)*($R$5>=5)+IFERROR(LARGE($F7:$O7,6),0)*($R$5>=6)+IFERROR(LARGE($F7:$O7,7),0)*($R$5>=7)+IFERROR(LARGE($F7:$O7,8),0)*($R$5>=8)+IFERROR(LARGE($F7:$O7,9),0)*($R$5>=9)+IFERROR(LARGE($F7:$O7,10),0)*($R$5>=10),1)) | Q7: =IF(N($P7)=0,"",$P7/MIN($R$5,COUNT($F7:$O7))) | R7: =IFERROR(LARGE(Resultaten!$AC$7:$AC$66,1),"") | S7: =IF($R7="","",MATCH($R7,Resultaten!$AC$7:$AC$66,0))
E8: =IF($S7="","","Op 100 schutters") | F8: =IF($S7="","",INDEX(Resultaten!$O$7:$X$66,$S7,1)) | G8: =IF($S7="","",INDEX(Resultaten!$O$7:$X$66,$S7,2)) | H8: =IF($S7="","",INDEX(Resultaten!$O$7:$X$66,$S7,3)) | I8: =IF($S7="","",INDEX(Resultaten!$O$7:$X$66,$S7,4)) | J8: =IF($S7="","",INDEX(Resultaten!$O$7:$X$66,$S7,5)) | K8: =IF($S7="","",INDEX(Resultaten!$O$7:$X$66,$S7,6)) | L8: =IF($S7="","",INDEX(Resultaten!$O$7:$X$66,$S7,7)) | M8: =IF($S7="","",INDEX(Resultaten!$O$7:$X$66,$S7,8)) | N8: =IF($S7="","",INDEX(Resultaten!$O$7:$X$66,$S7,9)) | O8: =IF($S7="","",INDEX(Resultaten!$O$7:$X$66,$S7,10)) | P8: =IF($S7="","",INDEX(Resultaten!$Y$7:$Y$66,$S7)) | Q8: =IF($S7="","",INDEX(Resultaten!$Z$7:$Z$66,$S7)) | S8: =$S7
A9: =IF($S9="","",INDEX(Resultaten!$AA$7:$AA$66,$S9)) | B9: =IF($S9="","",INDEX(Resultaten!$B$7:$B$66,$S9)) | C9: =IF($S9="","",INDEX(Resultaten!$C$7:$C$66,$S9)) | D9: =IF($S9="","",INDEX(Resultaten!$D$7:$D$66,$S9)) | E9: =IF($S9="","","Geschoten") | F9: =IF($S9="","",IF(INDEX(Resultaten!$E$7:$N$66,$S9,1)="","",INDEX(Resultaten!$E$7:$N$66,$S9,1))) | G9: =IF($S9="","",IF(INDEX(Resultaten!$E$7:$N$66,$S9,2)="","",INDEX(Resultaten!$E$7:$N$66,$S9,2))) | H9: =IF($S9="","",IF(INDEX(Resultaten!$E$7:$N$66,$S9,3)="","",INDEX(Resultaten!$E$7:$N$66,$S9,3))) | I9: =IF($S9="","",IF(INDEX(Resultaten!$E$7:$N$66,$S9,4)="","",INDEX(Resultaten!$E$7:$N$66,$S9,4))) | J9: =IF($S9="","",IF(INDEX(Resultaten!$E$7:$N$66,$S9,5)="","",INDEX(Resultaten!$E$7:$N$66,$S9,5))) | K9: =IF($S9="","",IF(INDEX(Resultaten!$E$7:$N$66,$S9,6)="","",INDEX(Resultaten!$E$7:$N$66,$S9,6))) | L9: =IF($S9="","",IF(INDEX(Resultaten!$E$7:$N$66,$S9,7)="","",INDEX(Resultaten!$E$7:$N$66,$S9,7))) | M9: =IF($S9="","",IF(INDEX(Resultaten!$E$7:$N$66,$S9,8)="","",INDEX(Resultaten!$E$7:$N$66,$S9,8))) | N9: =IF($S9="","",IF(INDEX(Resultaten!$E$7:$N$66,$S9,9)="","",INDEX(Resultaten!$E$7:$N$66,$S9,9))) | O9: =IF($S9="","",IF(INDEX(Resultaten!$E$7:$N$66,$S9,10)="","",INDEX(Resultaten!$E$7:$N$66,$S9,10))) | P9: =IF(OR($S9="",COUNT($F9:$O9)=0),"",ROUND(IFERROR(LARGE($F9:$O9,1),0)*($R$5>=1)+IFERROR(LARGE($F9:$O9,2),0)*($R$5>=2)+IFERROR(LARGE($F9:$O9,3),0)*($R$5>=3)+IFERROR(LARGE($F9:$O9,4),0)*($R$5>=4)+IFERROR(LARGE($F9:$O9,5),0)*($R$5>=5)+IFERROR(LARGE($F9:$O9,6),0)*($R$5>=6)+IFERROR(LARGE($F9:$O9,7),0)*($R$5>=7)+IFERROR(LARGE($F9:$O9,8),0)*($R$5>=8)+IFERROR(LARGE($F9:$O9,9),0)*($R$5>=9)+IFERROR(LARGE($F9:$O9,10),0)*($R$5>=10),1)) | Q9: =IF(N($P9)=0,"",$P9/MIN($R$5,COUNT($F9:$O9))) | R9: =IFERROR(LARGE(Resultaten!$AC$7:$AC$66,2),"") | S9: =IF($R9="","",MATCH($R9,Resultaten!$AC$7:$AC$66,0))
E10: =IF($S9="","","Op 100 schutters") | F10: =IF($S9="","",INDEX(Resultaten!$O$7:$X$66,$S9,1)) | G10: =IF($S9="","",INDEX(Resultaten!$O$7:$X$66,$S9,2)) | H10: =IF($S9="","",INDEX(Resultaten!$O$7:$X$66,$S9,3)) | I10: =IF($S9="","",INDEX(Resultaten!$O$7:$X$66,$S9,4)) | J10: =IF($S9="","",INDEX(Resultaten!$O$7:$X$66,$S9,5)) | K10: =IF($S9="","",INDEX(Resultaten!$O$7:$X$66,$S9,6)) | L10: =IF($S9="","",INDEX(Resultaten!$O$7:$X$66,$S9,7)) | M10: =IF($S9="","",INDEX(Resultaten!$O$7:$X$66,$S9,8)) | N10: =IF($S9="","",INDEX(Resultaten!$O$7:$X$66,$S9,9)) | O10: =IF($S9="","",INDEX(Resultaten!$O$7:$X$66,$S9,10)) | P10: =IF($S9="","",INDEX(Resultaten!$Y$7:$Y$66,$S9)) | Q10: =IF($S9="","",INDEX(Resultaten!$Z$7:$Z$66,$S9)) | S10: =$S9
A11: =IF($S11="","",INDEX(Resultaten!$AA$7:$AA$66,$S11)) | B11: =IF($S11="","",INDEX(Resultaten!$B$7:$B$66,$S11)) | C11: =IF($S11="","",INDEX(Resultaten!$C$7:$C$66,$S11)) | D11: =IF($S11="","",INDEX(Resultaten!$D$7:$D$66,$S11)) | E11: =IF($S11="","","Geschoten") | F11: =IF($S11="","",IF(INDEX(Resultaten!$E$7:$N$66,$S11,1)="","",INDEX(Resultaten!$E$7:$N$66,$S11,1))) | G11: =IF($S11="","",IF(INDEX(Resultaten!$E$7:$N$66,$S11,2)="","",INDEX(Resultaten!$E$7:$N$66,$S11,2))) | H11: =IF($S11="","",IF(INDEX(Resultaten!$E$7:$N$66,$S11,3)="","",INDEX(Resultaten!$E$7:$N$66,$S11,3))) | I11: =IF($S11="","",IF(INDEX(Resultaten!$E$7:$N$66,$S11,4)="","",INDEX(Resultaten!$E$7:$N$66,$S11,4))) | J11: =IF($S11="","",IF(INDEX(Resultaten!$E$7:$N$66,$S11,5)="","",INDEX(Resultaten!$E$7:$N$66,$S11,5))) | K11: =IF($S11="","",IF(INDEX(Resultaten!$E$7:$N$66,$S11,6)="","",INDEX(Resultaten!$E$7:$N$66,$S11,6))) | L11: =IF($S11="","",IF(INDEX(Resultaten!$E$7:$N$66,$S11,7)="","",INDEX(Resultaten!$E$7:$N$66,$S11,7))) | M11: =IF($S11="","",IF(INDEX(Resultaten!$E$7:$N$66,$S11,8)="","",INDEX(Resultaten!$E$7:$N$66,$S11,8))) | N11: =IF($S11="","",IF(INDEX(Resultaten!$E$7:$N$66,$S11,9)="","",INDEX(Resultaten!$E$7:$N$66,$S11,9))) | O11: =IF($S11="","",IF(INDEX(Resultaten!$E$7:$N$66,$S11,10)="","",INDEX(Resultaten!$E$7:$N$66,$S11,10))) | P11: =IF(OR($S11="",COUNT($F11:$O11)=0),"",ROUND(IFERROR(LARGE($F11:$O11,1),0)*($R$5>=1)+IFERROR(LARGE($F11:$O11,2),0)*($R$5>=2)+IFERROR(LARGE($F11:$O11,3),0)*($R$5>=3)+IFERROR(LARGE($F11:$O11,4),0)*($R$5>=4)+IFERROR(LARGE($F11:$O11,5),0)*($R$5>=5)+IFERROR(LARGE($F11:$O11,6),0)*($R$5>=6)+IFERROR(LARGE($F11:$O11,7),0)*($R$5>=7)+IFERROR(LARGE($F11:$O11,8),0)*($R$5>=8)+IFERROR(LARGE($F11:$O11,9),0)*($R$5>=9)+IFERROR(LARGE($F11:$O11,10),0)*($R$5>=10),1)) | Q11: =IF(N($P11)=0,"",$P11/MIN($R$5,COUNT($F11:$O11))) | R11: =IFERROR(LARGE(Resultaten!$AC$7:$AC$66,3),"") | S11: =IF($R11="","",MATCH($R11,Resultaten!$AC$7:$AC$66,0))
E12: =IF($S11="","","Op 100 schutters") | F12: =IF($S11="","",INDEX(Resultaten!$O$7:$X$66,$S11,1)) | G12: =IF($S11="","",INDEX(Resultaten!$O$7:$X$66,$S11,2)) | H12: =IF($S11="","",INDEX(Resultaten!$O$7:$X$66,$S11,3)) | I12: =IF($S11="","",INDEX(Resultaten!$O$7:$X$66,$S11,4)) | J12: =IF($S11="","",INDEX(Resultaten!$O$7:$X$66,$S11,5)) | K12: =IF($S11="","",INDEX(Resultaten!$O$7:$X$66,$S11,6)) | L12: =IF($S11="","",INDEX(Resultaten!$O$7:$X$66,$S11,7)) | M12: =IF($S11="","",INDEX(Resultaten!$O$7:$X$66,$S11,8)) | N12: =IF($S11="","",INDEX(Resultaten!$O$7:$X$66,$S11,9)) | O12: =IF($S11="","",INDEX(Resultaten!$O$7:$X$66,$S11,10)) | P12: =IF($S11="","",INDEX(Resultaten!$Y$7:$Y$66,$S11)) | Q12: =IF($S11="","",INDEX(Resultaten!$Z$7:$Z$66,$S11)) | S12: =$S11
A13: =IF($S13="","",INDEX(Resultaten!$AA$7:$AA$66,$S13)) | B13: =IF($S13="","",INDEX(Resultaten!$B$7:$B$66,$S13)) | C13: =IF($S13="","",INDEX(Resultaten!$C$7:$C$66,$S13)) | D13: =IF($S13="","",INDEX(Resultaten!$D$7:$D$66,$S13)) | E13: =IF($S13="","","Geschoten") | F13: =IF($S13="","",IF(INDEX(Resultaten!$E$7:$N$66,$S13,1)="","",INDEX(Resultaten!$E$7:$N$66,$S13,1))) | G13: =IF($S13="","",IF(INDEX(Resultaten!$E$7:$N$66,$S13,2)="","",INDEX(Resultaten!$E$7:$N$66,$S13,2))) | H13: =IF($S13="","",IF(INDEX(Resultaten!$E$7:$N$66,$S13,3)="","",INDEX(Resultaten!$E$7:$N$66,$S13,3))) | I13: =IF($S13="","",IF(INDEX(Resultaten!$E$7:$N$66,$S13,4)="","",INDEX(Resultaten!$E$7:$N$66,$S13,4))) | J13: =IF($S13="","",IF(INDEX(Resultaten!$E$7:$N$66,$S13,5)="","",INDEX(Resultaten!$E$7:$N$66,$S13,5))) | K13: =IF($S13="","",IF(INDEX(Resultaten!$E$7:$N$66,$S13,6)="","",INDEX(Resultaten!$E$7:$N$66,$S13,6))) | L13: =IF($S13="","",IF(INDEX(Resultaten!$E$7:$N$66,$S13,7)="","",INDEX(Resultaten!$E$7:$N$66,$S13,7))) | M13: =IF($S13="","",IF(INDEX(Resultaten!$E$7:$N$66,$S13,8)="","",INDEX(Resultaten!$E$7:$N$66,$S13,8))) | N13: =IF($S13="","",IF(INDEX(Resultaten!$E$7:$N$66,$S13,9)="","",INDEX(Resultaten!$E$7:$N$66,$S13,9))) | O13: =IF($S13="","",IF(INDEX(Resultaten!$E$7:$N$66,$S13,10)="","",INDEX(Resultaten!$E$7:$N$66,$S13,10))) | P13: =IF(OR($S13="",COUNT($F13:$O13)=0),"",ROUND(IFERROR(LARGE($F13:$O13,1),0)*($R$5>=1)+IFERROR(LARGE($F13:$O13,2),0)*($R$5>=2)+IFERROR(LARGE($F13:$O13,3),0)*($R$5>=3)+IFERROR(LARGE($F13:$O13,4),0)*($R$5>=4)+IFERROR(LARGE($F13:$O13,5),0)*($R$5>=5)+IFERROR(LARGE($F13:$O13,6),0)*($R$5>=6)+IFERROR(LARGE($F13:$O13,7),0)*($R$5>=7)+IFERROR(LARGE($F13:$O13,8),0)*($R$5>=8)+IFERROR(LARGE($F13:$O13,9),0)*($R$5>=9)+IFERROR(LARGE($F13:$O13,10),0)*($R$5>=10),1)) | Q13: =IF(N($P13)=0,"",$P13/MIN($R$5,COUNT($F13:$O13))) | R13: =IFERROR(LARGE(Resultaten!$AC$7:$AC$66,4),"") | S13: =IF($R13="","",MATCH($R13,Resultaten!$AC$7:$AC$66,0))
E14: =IF($S13="","","Op 100 schutters") | F14: =IF($S13="","",INDEX(Resultaten!$O$7:$X$66,$S13,1)) | G14: =IF($S13="","",INDEX(Resultaten!$O$7:$X$66,$S13,2)) | H14: =IF($S13="","",INDEX(Resultaten!$O$7:$X$66,$S13,3)) | I14: =IF($S13="","",INDEX(Resultaten!$O$7:$X$66,$S13,4)) | J14: =IF($S13="","",INDEX(Resultaten!$O$7:$X$66,$S13,5)) | K14: =IF($S13="","",INDEX(Resultaten!$O$7:$X$66,$S13,6)) | L14: =IF($S13="","",INDEX(Resultaten!$O$7:$X$66,$S13,7)) | M14: =IF($S13="","",INDEX(Resultaten!$O$7:$X$66,$S13,8)) | N14: =IF($S13="","",INDEX(Resultaten!$O$7:$X$66,$S13,9)) | O14: =IF($S13="","",INDEX(Resultaten!$O$7:$X$66,$S13,10)) | P14: =IF($S13="","",INDEX(Resultaten!$Y$7:$Y$66,$S13)) | Q14: =IF($S13="","",INDEX(Resultaten!$Z$7:$Z$66,$S13)) | S14: =$S13
A15: =IF($S15="","",INDEX(Resultaten!$AA$7:$AA$66,$S15)) | B15: =IF($S15="","",INDEX(Resultaten!$B$7:$B$66,$S15)) | C15: =IF($S15="","",INDEX(Resultaten!$C$7:$C$66,$S15)) | D15: =IF($S15="","",INDEX(Resultaten!$D$7:$D$66,$S15)) | E15: =IF($S15="","","Geschoten") | F15: =IF($S15="","",IF(INDEX(Resultaten!$E$7:$N$66,$S15,1)="","",INDEX(Resultaten!$E$7:$N$66,$S15,1))) | G15: =IF($S15="","",IF(INDEX(Resultaten!$E$7:$N$66,$S15,2)="","",INDEX(Resultaten!$E$7:$N$66,$S15,2))) | H15: =IF($S15="","",IF(INDEX(Resultaten!$E$7:$N$66,$S15,3)="","",INDEX(Resultaten!$E$7:$N$66,$S15,3))) | I15: =IF($S15="","",IF(INDEX(Resultaten!$E$7:$N$66,$S15,4)="","",INDEX(Resultaten!$E$7:$N$66,$S15,4))) | J15: =IF($S15="","",IF(INDEX(Resultaten!$E$7:$N$66,$S15,5)="","",INDEX(Resultaten!$E$7:$N$66,$S15,5))) | K15: =IF($S15="","",IF(INDEX(Resultaten!$E$7:$N$66,$S15,6)="","",INDEX(Resultaten!$E$7:$N$66,$S15,6))) | L15: =IF($S15="","",IF(INDEX(Resultaten!$E$7:$N$66,$S15,7)="","",INDEX(Resultaten!$E$7:$N$66,$S15,7))) | M15: =IF($S15="","",IF(INDEX(Resultaten!$E$7:$N$66,$S15,8)="","",INDEX(Resultaten!$E$7:$N$66,$S15,8))) | N15: =IF($S15="","",IF(INDEX(Resultaten!$E$7:$N$66,$S15,9)="","",INDEX(Resultaten!$E$7:$N$66,$S15,9))) | O15: =IF($S15="","",IF(INDEX(Resultaten!$E$7:$N$66,$S15,10)="","",INDEX(Resultaten!$E$7:$N$66,$S15,10))) | P15: =IF(OR($S15="",COUNT($F15:$O15)=0),"",ROUND(IFERROR(LARGE($F15:$O15,1),0)*($R$5>=1)+IFERROR(LARGE($F15:$O15,2),0)*($R$5>=2)+IFERROR(LARGE($F15:$O15,3),0)*($R$5>=3)+IFERROR(LARGE($F15:$O15,4),0)*($R$5>=4)+IFERROR(LARGE($F15:$O15,5),0)*($R$5>=5)+IFERROR(LARGE($F15:$O15,6),0)*($R$5>=6)+IFERROR(LARGE($F15:$O15,7),0)*($R$5>=7)+IFERROR(LARGE($F15:$O15,8),0)*($R$5>=8)+IFERROR(LARGE($F15:$O15,9),0)*($R$5>=9)+IFERROR(LARGE($F15:$O15,10),0)*($R$5>=10),1)) | Q15: =IF(N($P15)=0,"",$P15/MIN($R$5,COUNT($F15:$O15))) | R15: =IFERROR(LARGE(Resultaten!$AC$7:$AC$66,5),"") | S15: =IF($R15="","",MATCH($R15,Resultaten!$AC$7:$AC$66,0))
E16: =IF($S15="","","Op 100 schutters") | F16: =IF($S15="","",INDEX(Resultaten!$O$7:$X$66,$S15,1)) | G16: =IF($S15="","",INDEX(Resultaten!$O$7:$X$66,$S15,2)) | H16: =IF($S15="","",INDEX(Resultaten!$O$7:$X$66,$S15,3)) | I16: =IF($S15="","",INDEX(Resultaten!$O$7:$X$66,$S15,4)) | J16: =IF($S15="","",INDEX(Resultaten!$O$7:$X$66,$S15,5)) | K16: =IF($S15="","",INDEX(Resultaten!$O$7:$X$66,$S15,6)) | L16: =IF($S15="","",INDEX(Resultaten!$O$7:$X$66,$S15,7)) | M16: =IF($S15="","",INDEX(Resultaten!$O$7:$X$66,$S15,8)) | N16: =IF($S15="","",INDEX(Resultaten!$O$7:$X$66,$S15,9)) | O16: =IF($S15="","",INDEX(Resultaten!$O$7:$X$66,$S15,10)) | P16: =IF($S15="","",INDEX(Resultaten!$Y$7:$Y$66,$S15)) | Q16: =IF($S15="","",INDEX(Resultaten!$Z$7:$Z$66,$S15)) | S16: =$S15
A17: =IF($S17="","",INDEX(Resultaten!$AA$7:$AA$66,$S17)) | B17: =IF($S17="","",INDEX(Resultaten!$B$7:$B$66,$S17)) | C17: =IF($S17="","",INDEX(Resultaten!$C$7:$C$66,$S17)) | D17: =IF($S17="","",INDEX(Resultaten!$D$7:$D$66,$S17)) | E17: =IF($S17="","","Geschoten") | F17: =IF($S17="","",IF(INDEX(Resultaten!$E$7:$N$66,$S17,1)="","",INDEX(Resultaten!$E$7:$N$66,$S17,1))) | G17: =IF($S17="","",IF(INDEX(Resultaten!$E$7:$N$66,$S17,2)="","",INDEX(Resultaten!$E$7:$N$66,$S17,2))) | H17: =IF($S17="","",IF(INDEX(Resultaten!$E$7:$N$66,$S17,3)="","",INDEX(Resultaten!$E$7:$N$66,$S17,3))) | I17: =IF($S17="","",IF(INDEX(Resultaten!$E$7:$N$66,$S17,4)="","",INDEX(Resultaten!$E$7:$N$66,$S17,4))) | J17: =IF($S17="","",IF(INDEX(Resultaten!$E$7:$N$66,$S17,5)="","",INDEX(Resultaten!$E$7:$N$66,$S17,5))) | K17: =IF($S17="","",IF(INDEX(Resultaten!$E$7:$N$66,$S17,6)="","",INDEX(Resultaten!$E$7:$N$66,$S17,6))) | L17: =IF($S17="","",IF(INDEX(Resultaten!$E$7:$N$66,$S17,7)="","",INDEX(Resultaten!$E$7:$N$66,$S17,7))) | M17: =IF($S17="","",IF(INDEX(Resultaten!$E$7:$N$66,$S17,8)="","",INDEX(Resultaten!$E$7:$N$66,$S17,8))) | N17: =IF($S17="","",IF(INDEX(Resultaten!$E$7:$N$66,$S17,9)="","",INDEX(Resultaten!$E$7:$N$66,$S17,9))) | O17: =IF($S17="","",IF(INDEX(Resultaten!$E$7:$N$66,$S17,10)="","",INDEX(Resultaten!$E$7:$N$66,$S17,10))) | P17: =IF(OR($S17="",COUNT($F17:$O17)=0),"",ROUND(IFERROR(LARGE($F17:$O17,1),0)*($R$5>=1)+IFERROR(LARGE($F17:$O17,2),0)*($R$5>=2)+IFERROR(LARGE($F17:$O17,3),0)*($R$5>=3)+IFERROR(LARGE($F17:$O17,4),0)*($R$5>=4)+IFERROR(LARGE($F17:$O17,5),0)*($R$5>=5)+IFERROR(LARGE($F17:$O17,6),0)*($R$5>=6)+IFERROR(LARGE($F17:$O17,7),0)*($R$5>=7)+IFERROR(LARGE($F17:$O17,8),0)*($R$5>=8)+IFERROR(LARGE($F17:$O17,9),0)*($R$5>=9)+IFERROR(LARGE($F17:$O17,10),0)*($R$5>=10),1)) | Q17: =IF(N($P17)=0,"",$P17/MIN($R$5,COUNT($F17:$O17))) | R17: =IFERROR(LARGE(Resultaten!$AC$7:$AC$66,6),"") | S17: =IF($R17="","",MATCH($R17,Resultaten!$AC$7:$AC$66,0))
E18: =IF($S17="","","Op 100 schutters") | F18: =IF($S17="","",INDEX(Resultaten!$O$7:$X$66,$S17,1)) | G18: =IF($S17="","",INDEX(Resultaten!$O$7:$X$66,$S17,2)) | H18: =IF($S17="","",INDEX(Resultaten!$O$7:$X$66,$S17,3)) | I18: =IF($S17="","",INDEX(Resultaten!$O$7:$X$66,$S17,4)) | J18: =IF($S17="","",INDEX(Resultaten!$O$7:$X$66,$S17,5)) | K18: =IF($S17="","",INDEX(Resultaten!$O$7:$X$66,$S17,6)) | L18: =IF($S17="","",INDEX(Resultaten!$O$7:$X$66,$S17,7)) | M18: =IF($S17="","",INDEX(Resultaten!$O$7:$X$66,$S17,8)) | N18: =IF($S17="","",INDEX(Resultaten!$O$7:$X$66,$S17,9)) | O18: =IF($S17="","",INDEX(Resultaten!$O$7:$X$66,$S17,10)) | P18: =IF($S17="","",INDEX(Resultaten!$Y$7:$Y$66,$S17)) | Q18: =IF($S17="","",INDEX(Resultaten!$Z$7:$Z$66,$S17)) | S18: =$S17
A19: =IF($S19="","",INDEX(Resultaten!$AA$7:$AA$66,$S19)) | B19: =IF($S19="","",INDEX(Resultaten!$B$7:$B$66,$S19)) | C19: =IF($S19="","",INDEX(Resultaten!$C$7:$C$66,$S19)) | D19: =IF($S19="","",INDEX(Resultaten!$D$7:$D$66,$S19)) | E19: =IF($S19="","","Geschoten") | F19: =IF($S19="","",IF(INDEX(Resultaten!$E$7:$N$66,$S19,1)="","",INDEX(Resultaten!$E$7:$N$66,$S19,1))) | G19: =IF($S19="","",IF(INDEX(Resultaten!$E$7:$N$66,$S19,2)="","",INDEX(Resultaten!$E$7:$N$66,$S19,2))) | H19: =IF($S19="","",IF(INDEX(Resultaten!$E$7:$N$66,$S19,3)="","",INDEX(Resultaten!$E$7:$N$66,$S19,3))) | I19: =IF($S19="","",IF(INDEX(Resultaten!$E$7:$N$66,$S19,4)="","",INDEX(Resultaten!$E$7:$N$66,$S19,4))) | J19: =IF($S19="","",IF(INDEX(Resultaten!$E$7:$N$66,$S19,5)="","",INDEX(Resultaten!$E$7:$N$66,$S19,5))) | K19: =IF($S19="","",IF(INDEX(Resultaten!$E$7:$N$66,$S19,6)="","",INDEX(Resultaten!$E$7:$N$66,$S19,6))) | L19: =IF($S19="","",IF(INDEX(Resultaten!$E$7:$N$66,$S19,7)="","",INDEX(Resultaten!$E$7:$N$66,$S19,7))) | M19: =IF($S19="","",IF(INDEX(Resultaten!$E$7:$N$66,$S19,8)="","",INDEX(Resultaten!$E$7:$N$66,$S19,8))) | N19: =IF($S19="","",IF(INDEX(Resultaten!$E$7:$N$66,$S19,9)="","",INDEX(Resultaten!$E$7:$N$66,$S19,9))) | O19: =IF($S19="","",IF(INDEX(Resultaten!$E$7:$N$66,$S19,10)="","",INDEX(Resultaten!$E$7:$N$66,$S19,10))) | P19: =IF(OR($S19="",COUNT($F19:$O19)=0),"",ROUND(IFERROR(LARGE($F19:$O19,1),0)*($R$5>=1)+IFERROR(LARGE($F19:$O19,2),0)*($R$5>=2)+IFERROR(LARGE($F19:$O19,3),0)*($R$5>=3)+IFERROR(LARGE($F19:$O19,4),0)*($R$5>=4)+IFERROR(LARGE($F19:$O19,5),0)*($R$5>=5)+IFERROR(LARGE($F19:$O19,6),0)*($R$5>=6)+IFERROR(LARGE($F19:$O19,7),0)*($R$5>=7)+IFERROR(LARGE($F19:$O19,8),0)*($R$5>=8)+IFERROR(LARGE($F19:$O19,9),0)*($R$5>=9)+IFERROR(LARGE($F19:$O19,10),0)*($R$5>=10),1)) | Q19: =IF(N($P19)=0,"",$P19/MIN($R$5,COUNT($F19:$O19))) | R19: =IFERROR(LARGE(Resultaten!$AC$7:$AC$66,7),"") | S19: =IF($R19="","",MATCH($R19,Resultaten!$AC$7:$AC$66,0))
E20: =IF($S19="","","Op 100 schutters") | F20: =IF($S19="","",INDEX(Resultaten!$O$7:$X$66,$S19,1)) | G20: =IF($S19="","",INDEX(Resultaten!$O$7:$X$66,$S19,2)) | H20: =IF($S19="","",INDEX(Resultaten!$O$7:$X$66,$S19,3)) | I20: =IF($S19="","",INDEX(Resultaten!$O$7:$X$66,$S19,4)) | J20: =IF($S19="","",INDEX(Resultaten!$O$7:$X$66,$S19,5)) | K20: =IF($S19="","",INDEX(Resultaten!$O$7:$X$66,$S19,6)) | L20: =IF($S19="","",INDEX(Resultaten!$O$7:$X$66,$S19,7)) | M20: =IF($S19="","",INDEX(Resultaten!$O$7:$X$66,$S19,8)) | N20: =IF($S19="","",INDEX(Resultaten!$O$7:$X$66,$S19,9)) | O20: =IF($S19="","",INDEX(Resultaten!$O$7:$X$66,$S19,10)) | P20: =IF($S19="","",INDEX(Resultaten!$Y$7:$Y$66,$S19)) | Q20: =IF($S19="","",INDEX(Resultaten!$Z$7:$Z$66,$S19)) | S20: =$S19
A21: =IF($S21="","",INDEX(Resultaten!$AA$7:$AA$66,$S21)) | B21: =IF($S21="","",INDEX(Resultaten!$B$7:$B$66,$S21)) | C21: =IF($S21="","",INDEX(Resultaten!$C$7:$C$66,$S21)) | D21: =IF($S21="","",INDEX(Resultaten!$D$7:$D$66,$S21)) | E21: =IF($S21="","","Geschoten") | F21: =IF($S21="","",IF(INDEX(Resultaten!$E$7:$N$66,$S21,1)="","",INDEX(Resultaten!$E$7:$N$66,$S21,1))) | G21: =IF($S21="","",IF(INDEX(Resultaten!$E$7:$N$66,$S21,2)="","",INDEX(Resultaten!$E$7:$N$66,$S21,2))) | H21: =IF($S21="","",IF(INDEX(Resultaten!$E$7:$N$66,$S21,3)="","",INDEX(Resultaten!$E$7:$N$66,$S21,3))) | I21: =IF($S21="","",IF(INDEX(Resultaten!$E$7:$N$66,$S21,4)="","",INDEX(Resultaten!$E$7:$N$66,$S21,4))) | J21: =IF($S21="","",IF(INDEX(Resultaten!$E$7:$N$66,$S21,5)="","",INDEX(Resultaten!$E$7:$N$66,$S21,5))) | K21: =IF($S21="","",IF(INDEX(Resultaten!$E$7:$N$66,$S21,6)="","",INDEX(Resultaten!$E$7:$N$66,$S21,6))) | L21: =IF($S21="","",IF(INDEX(Resultaten!$E$7:$N$66,$S21,7)="","",INDEX(Resultaten!$E$7:$N$66,$S21,7))) | M21: =IF($S21="","",IF(INDEX(Resultaten!$E$7:$N$66,$S21,8)="","",INDEX(Resultaten!$E$7:$N$66,$S21,8))) | N21: =IF($S21="","",IF(INDEX(Resultaten!$E$7:$N$66,$S21,9)="","",INDEX(Resultaten!$E$7:$N$66,$S21,9))) | O21: =IF($S21="","",IF(INDEX(Resultaten!$E$7:$N$66,$S21,10)="","",INDEX(Resultaten!$E$7:$N$66,$S21,10))) | P21: =IF(OR($S21="",COUNT($F21:$O21)=0),"",ROUND(IFERROR(LARGE($F21:$O21,1),0)*($R$5>=1)+IFERROR(LARGE($F21:$O21,2),0)*($R$5>=2)+IFERROR(LARGE($F21:$O21,3),0)*($R$5>=3)+IFERROR(LARGE($F21:$O21,4),0)*($R$5>=4)+IFERROR(LARGE($F21:$O21,5),0)*($R$5>=5)+IFERROR(LARGE($F21:$O21,6),0)*($R$5>=6)+IFERROR(LARGE($F21:$O21,7),0)*($R$5>=7)+IFERROR(LARGE($F21:$O21,8),0)*($R$5>=8)+IFERROR(LARGE($F21:$O21,9),0)*($R$5>=9)+IFERROR(LARGE($F21:$O21,10),0)*($R$5>=10),1)) | Q21: =IF(N($P21)=0,"",$P21/MIN($R$5,COUNT($F21:$O21))) | R21: =IFERROR(LARGE(Resultaten!$AC$7:$AC$66,8),"") | S21: =IF($R21="","",MATCH($R21,Resultaten!$AC$7:$AC$66,0))
E22: =IF($S21="","","Op 100 schutters") | F22: =IF($S21="","",INDEX(Resultaten!$O$7:$X$66,$S21,1)) | G22: =IF($S21="","",INDEX(Resultaten!$O$7:$X$66,$S21,2)) | H22: =IF($S21="","",INDEX(Resultaten!$O$7:$X$66,$S21,3)) | I22: =IF($S21="","",INDEX(Resultaten!$O$7:$X$66,$S21,4)) | J22: =IF($S21="","",INDEX(Resultaten!$O$7:$X$66,$S21,5)) | K22: =IF($S21="","",INDEX(Resultaten!$O$7:$X$66,$S21,6)) | L22: =IF($S21="","",INDEX(Resultaten!$O$7:$X$66,$S21,7)) | M22: =IF($S21="","",INDEX(Resultaten!$O$7:$X$66,$S21,8)) | N22: =IF($S21="","",INDEX(Resultaten!$O$7:$X$66,$S21,9)) | O22: =IF($S21="","",INDEX(Resultaten!$O$7:$X$66,$S21,10)) | P22: =IF($S21="","",INDEX(Resultaten!$Y$7:$Y$66,$S21)) | Q22: =IF($S21="","",INDEX(Resultaten!$Z$7:$Z$66,$S21)) | S22: =$S21
A23: =IF($S23="","",INDEX(Resultaten!$AA$7:$AA$66,$S23)) | B23: =IF($S23="","",INDEX(Resultaten!$B$7:$B$66,$S23)) | C23: =IF($S23="","",INDEX(Resultaten!$C$7:$C$66,$S23)) | D23: =IF($S23="","",INDEX(Resultaten!$D$7:$D$66,$S23)) | E23: =IF($S23="","","Geschoten") | F23: =IF($S23="","",IF(INDEX(Resultaten!$E$7:$N$66,$S23,1)="","",INDEX(Resultaten!$E$7:$N$66,$S23,1))) | G23: =IF($S23="","",IF(INDEX(Resultaten!$E$7:$N$66,$S23,2)="","",INDEX(Resultaten!$E$7:$N$66,$S23,2))) | H23: =IF($S23="","",IF(INDEX(Resultaten!$E$7:$N$66,$S23,3)="","",INDEX(Resultaten!$E$7:$N$66,$S23,3))) | I23: =IF($S23="","",IF(INDEX(Resultaten!$E$7:$N$66,$S23,4)="","",INDEX(Resultaten!$E$7:$N$66,$S23,4))) | J23: =IF($S23="","",IF(INDEX(Resultaten!$E$7:$N$66,$S23,5)="","",INDEX(Resultaten!$E$7:$N$66,$S23,5))) | K23: =IF($S23="","",IF(INDEX(Resultaten!$E$7:$N$66,$S23,6)="","",INDEX(Resultaten!$E$7:$N$66,$S23,6))) | L23: =IF($S23="","",IF(INDEX(Resultaten!$E$7:$N$66,$S23,7)="","",INDEX(Resultaten!$E$7:$N$66,$S23,7))) | M23: =IF($S23="","",IF(INDEX(Resultaten!$E$7:$N$66,$S23,8)="","",INDEX(Resultaten!$E$7:$N$66,$S23,8))) | N23: =IF($S23="","",IF(INDEX(Resultaten!$E$7:$N$66,$S23,9)="","",INDEX(Resultaten!$E$7:$N$66,$S23,9))) | O23: =IF($S23="","",IF(INDEX(Resultaten!$E$7:$N$66,$S23,10)="","",INDEX(Resultaten!$E$7:$N$66,$S23,10))) | P23: =IF(OR($S23="",COUNT($F23:$O23)=0),"",ROUND(IFERROR(LARGE($F23:$O23,1),0)*($R$5>=1)+IFERROR(LARGE($F23:$O23,2),0)*($R$5>=2)+IFERROR(LARGE($F23:$O23,3),0)*($R$5>=3)+IFERROR(LARGE($F23:$O23,4),0)*($R$5>=4)+IFERROR(LARGE($F23:$O23,5),0)*($R$5>=5)+IFERROR(LARGE($F23:$O23,6),0)*($R$5>=6)+IFERROR(LARGE($F23:$O23,7),0)*($R$5>=7)+IFERROR(LARGE($F23:$O23,8),0)*($R$5>=8)+IFERROR(LARGE($F23:$O23,9),0)*($R$5>=9)+IFERROR(LARGE($F23:$O23,10),0)*($R$5>=10),1)) | Q23: =IF(N($P23)=0,"",$P23/MIN($R$5,COUNT($F23:$O23))) | R23: =IFERROR(LARGE(Resultaten!$AC$7:$AC$66,9),"") | S23: =IF($R23="","",MATCH($R23,Resultaten!$AC$7:$AC$66,0))
E24: =IF($S23="","","Op 100 schutters") | F24: =IF($S23="","",INDEX(Resultaten!$O$7:$X$66,$S23,1)) | G24: =IF($S23="","",INDEX(Resultaten!$O$7:$X$66,$S23,2)) | H24: =IF($S23="","",INDEX(Resultaten!$O$7:$X$66,$S23,3)) | I24: =IF($S23="","",INDEX(Resultaten!$O$7:$X$66,$S23,4)) | J24: =IF($S23="","",INDEX(Resultaten!$O$7:$X$66,$S23,5)) | K24: =IF($S23="","",INDEX(Resultaten!$O$7:$X$66,$S23,6)) | L24: =IF($S23="","",INDEX(Resultaten!$O$7:$X$66,$S23,7)) | M24: =IF($S23="","",INDEX(Resultaten!$O$7:$X$66,$S23,8)) | N24: =IF($S23="","",INDEX(Resultaten!$O$7:$X$66,$S23,9)) | O24: =IF($S23="","",INDEX(Resultaten!$O$7:$X$66,$S23,10)) | P24: =IF($S23="","",INDEX(Resultaten!$Y$7:$Y$66,$S23)) | Q24: =IF($S23="","",INDEX(Resultaten!$Z$7:$Z$66,$S23)) | S24: =$S23
A25: =IF($S25="","",INDEX(Resultaten!$AA$7:$AA$66,$S25)) | B25: =IF($S25="","",INDEX(Resultaten!$B$7:$B$66,$S25)) | C25: =IF($S25="","",INDEX(Resultaten!$C$7:$C$66,$S25)) | D25: =IF($S25="","",INDEX(Resultaten!$D$7:$D$66,$S25)) | E25: =IF($S25="","","Geschoten") | F25: =IF($S25="","",IF(INDEX(Resultaten!$E$7:$N$66,$S25,1)="","",INDEX(Resultaten!$E$7:$N$66,$S25,1))) | G25: =IF($S25="","",IF(INDEX(Resultaten!$E$7:$N$66,$S25,2)="","",INDEX(Resultaten!$E$7:$N$66,$S25,2))) | H25: =IF($S25="","",IF(INDEX(Resultaten!$E$7:$N$66,$S25,3)="","",INDEX(Resultaten!$E$7:$N$66,$S25,3))) | I25: =IF($S25="","",IF(INDEX(Resultaten!$E$7:$N$66,$S25,4)="","",INDEX(Resultaten!$E$7:$N$66,$S25,4))) | J25: =IF($S25="","",IF(INDEX(Resultaten!$E$7:$N$66,$S25,5)="","",INDEX(Resultaten!$E$7:$N$66,$S25,5))) | K25: =IF($S25="","",IF(INDEX(Resultaten!$E$7:$N$66,$S25,6)="","",INDEX(Resultaten!$E$7:$N$66,$S25,6))) | L25: =IF($S25="","",IF(INDEX(Resultaten!$E$7:$N$66,$S25,7)="","",INDEX(Resultaten!$E$7:$N$66,$S25,7))) | M25: =IF($S25="","",IF(INDEX(Resultaten!$E$7:$N$66,$S25,8)="","",INDEX(Resultaten!$E$7:$N$66,$S25,8))) | N25: =IF($S25="","",IF(INDEX(Resultaten!$E$7:$N$66,$S25,9)="","",INDEX(Resultaten!$E$7:$N$66,$S25,9))) | O25: =IF($S25="","",IF(INDEX(Resultaten!$E$7:$N$66,$S25,10)="","",INDEX(Resultaten!$E$7:$N$66,$S25,10))) | P25: =IF(OR($S25="",COUNT($F25:$O25)=0),"",ROUND(IFERROR(LARGE($F25:$O25,1),0)*($R$5>=1)+IFERROR(LARGE($F25:$O25,2),0)*($R$5>=2)+IFERROR(LARGE($F25:$O25,3),0)*($R$5>=3)+IFERROR(LARGE($F25:$O25,4),0)*($R$5>=4)+IFERROR(LARGE($F25:$O25,5),0)*($R$5>=5)+IFERROR(LARGE($F25:$O25,6),0)*($R$5>=6)+IFERROR(LARGE($F25:$O25,7),0)*($R$5>=7)+IFERROR(LARGE($F25:$O25,8),0)*($R$5>=8)+IFERROR(LARGE($F25:$O25,9),0)*($R$5>=9)+IFERROR(LARGE($F25:$O25,10),0)*($R$5>=10),1)) | Q25: =IF(N($P25)=0,"",$P25/MIN($R$5,COUNT($F25:$O25))) | R25: =IFERROR(LARGE(Resultaten!$AC$7:$AC$66,10),"") | S25: =IF($R25="","",MATCH($R25,Resultaten!$AC$7:$AC$66,0))
